Workbook

Sheet DataSource
A1: 查询键 | B1: 干员ID | C1: 干员名称 | D1: 等级 | E1: 英文名 | F1: 职业 | G1: 阵营 | H1: 标签 | I1: 稀有度 | J1: 武器类型 | K1: 干员属性 | L1: 主属性 | M1: 副属性 | N1: 生命值 | O1: 攻击力 | P1: 防御力 | Q1: 力量 | R1: 敏捷 | S1: 智识 | T1: 意志 | U1: 暴击率 | V1: 暴击伤害 | W1: 普通攻击范围 | X1: 韧性削减系数 | Y1: 物理等级系数 | Z1: 法术等级系数 | AA1: 精英化等阶 | AB1: 潜能天赋① | AC1: 潜能天赋② | AD1: 潜能天赋③ | AE1: 潜能天赋④ | AF1: 潜能天赋⑤ | AG1: 信赖天赋节点① | AH1: 信赖天赋节点② | AI1: 信赖天赋节点③ | AJ1: 信赖天赋节点④ | AK1: 技能天赋节点①等级 | AL1: 技能天赋节点①效果 | AM1: __talent_skill_1_lv1 | AN1: __talent_skill_1_lv2 | AO1: __talent_skill_1_lv3 | AP1: 技能天赋节点②等级 | AQ1: 技能天赋节点②效果 | AR1: __talent_skill_2_lv1 | AS1: __talent_skill_2_lv2 | AT1: __talent_skill_2_lv3 | AV1: 1
A2: chr_0002_endminm_1 | B2: chr_0002_endminm | C2: 管理员(男) | D2: 1 | E2: Endministrator | F2: 近卫 | G2: ENDFIELD INDUSTRIES | H2: 猛击, 控制 | I2: 6★ | J2: 单手剑 | K2: 物理 | L2: 敏捷 | M2: 力量 | N2: 500 | O2: 30 | P2: 0 | Q2: 14.7422680412371 | R2: 14.2268041237113 | S2: 9.79381443298969 | T2: 10.8247422680412 | U2: 5.0% | V2: 50.0% | W2: 3 | X2: 0.14 | Y2: 1.0 | Z2: 1.0 | AA2: 0 | AB2: 【最后的苏醒】战技构成序列消耗源石结晶时，返还50点技力。 | AC2: 【权能映射】天赋本质瓦解效果加强：自身获得攻击力提升时，其他友方干员获得一半的攻击力提升效果。 | AD2: 【？？？】？？？ | AE2: 【？？？】？？？ | AF2: 【？？？】？？？ | AG2: 无 | AH2: 无 | AI2: 无 | AJ2: 无 | AK2: 1 | AL2: 无 | AM2: 无 | AN2: 无 | AO2: 无 | AP2: 1 | AQ2: 无 | AR2: 无 | AS2: 无 | AT2: 无 | AV2: 2
A3: chr_0002_endminm_2 | B3: chr_0002_endminm | C3: 管理员(男) | D3: 2 | E3: Endministrator | F3: 近卫 | G3: ENDFIELD INDUSTRIES | H3: 猛击, 控制 | I3: 6★ | J3: 单手剑 | K3: 物理 | L3: 敏捷 | M3: 力量 | N3: 556 | O3: 33 | P3: 0 | Q3: 15.966547443719742 | R3: 15.64948453608243 | S3: 10.773195876288662 | T3: 11.90721649484532 | U3: 5.0% | V3: 50.0% | W3: 3 | X3: 0.14 | Y3: 1.00255102040816 | Z3: 1.00510204081633 | AA3: 0 | AB3: 【最后的苏醒】战技构成序列消耗源石结晶时，返还50点技力。 | AC3: 【权能映射】天赋本质瓦解效果加强：自身获得攻击力提升时，其他友方干员获得一半的攻击力提升效果。 | AD3: 【？？？】？？？ | AE3: 【？？？】？？？ | AF3: 【？？？】？？？ | AG3: 无 | AH3: 无 | AI3: 无 | AJ3: 无 | AK3: 1 | AL3: 无 | AM3: 无 | AN3: 无 | AO3: 无 | AP3: 1 | AQ3: 无 | AR3: 无 | AS3: 无 | AT3: 无 | AV3: 3
A4: chr_0002_endminm_3 | B4: chr_0002_endminm | C4: 管理员(男) | D4: 3 | E4: Endministrator | F4: 近卫 | G4: ENDFIELD INDUSTRIES | H4: 猛击, 控制 | I4: 6★ | J4: 单手剑 | K4: 物理 | L4: 敏捷 | M4: 力量 | N4: 612 | O4: 36 | P4: 0 | Q4: 17.190826846202384 | R4: 17.07216494845356 | S4: 11.752577319587635 | T4: 12.989690721649442 | U4: 5.0% | V4: 50.0% | W4: 3 | X4: 0.14 | Y4: 1.00510204081633 | Z4: 1.01020408163265 | AA4: 0 | AB4: 【最后的苏醒】战技构成序列消耗源石结晶时，返还50点技力。 | AC4: 【权能映射】天赋本质瓦解效果加强：自身获得攻击力提升时，其他友方干员获得一半的攻击力提升效果。 | AD4: 【？？？】？？？ | AE4: 【？？？】？？？ | AF4: 【？？？】？？？ | AG4: 无 | AH4: 无 | AI4: 无 | AJ4: 无 | AK4: 1 | AL4: 无 | AM4: 无 | AN4: 无 | AO4: 无 | AP4: 1 | AQ4: 无 | AR4: 无 | AS4: 无 | AT4: 无 | AV4: 4
A5: chr_0002_endminm_4 | B5: chr_0002_endminm | C5: 管理员(男) | D5: 4 | E5: Endministrator | F5: 近卫 | G5: ENDFIELD INDUSTRIES | H5: 猛击, 控制 | I5: 6★ | J5: 单手剑 | K5: 物理 | L5: 敏捷 | M5: 力量 | N5: 668 | O5: 40 | P5: 0 | Q5: 18.415106248685024 | R5: 18.49484536082469 | S5: 12.731958762886606 | T5: 14.072164948453562 | U5: 5.0% | V5: 50.0% | W5: 3 | X5: 0.14 | Y5: 1.00765306122449 | Z5: 1.01530612244898 | AA5: 0 | AB5: 【最后的苏醒】战技构成序列消耗源石结晶时，返还50点技力。 | AC5: 【权能映射】天赋本质瓦解效果加强：自身获得攻击力提升时，其他友方干员获得一半的攻击力提升效果。 | AD5: 【？？？】？？？ | AE5: 【？？？】？？？ | AF5: 【？？？】？？？ | AG5: 无 | AH5: 无 | AI5: 无 | AJ5: 无 | AK5: 1 | AL5: 无 | AM5: 无 | AN5: 无 | AO5: 无 | AP5: 1 | AQ5: 无 | AR5: 无 | AS5: 无 | AT5: 无 | AV5: 5
A6: chr_0002_endminm_5 | B6: chr_0002_endminm | C6: 管理员(男) | D6: 5 | E6: Endministrator | F6: 近卫 | G6: ENDFIELD INDUSTRIES | H6: 猛击, 控制 | I6: 6★ | J6: 单手剑 | K6: 物理 | L6: 敏捷 | M6: 力量 | N6: 724 | O6: 43 | P6: 0 | Q6: 19.639385651167668 | R6: 19.91752577319582 | S6: 13.711340206185579 | T6: 15.154639175257682 | U6: 5.0% | V6: 50.0% | W6: 3 | X6: 0.14 | Y6: 1.01020408163265 | Z6: 1.02040816326531 | AA6: 0 | AB6: 【最后的苏醒】战技构成序列消耗源石结晶时，返还50点技力。 | AC6: 【权能映射】天赋本质瓦解效果加强：自身获得攻击力提升时，其他友方干员获得一半的攻击力提升效果。 | AD6: 【？？？】？？？ | AE6: 【？？？】？？？ | AF6: 【？？？】？？？ | AG6: 无 | AH6: 无 | AI6: 无 | AJ6: 无 | AK6: 1 | AL6: 无 | AM6: 无 | AN6: 无 | AO6: 无 | AP6: 1 | AQ6: 无 | AR6: 无 | AS6: 无 | AT6: 无 | AV6: 6
A7: chr_0002_endminm_6 | B7: chr_0002_endminm | C7: 管理员(男) | D7: 6 | E7: Endministrator | F7: 近卫 | G7: ENDFIELD INDUSTRIES | H7: 猛击, 控制 | I7: 6★ | J7: 单手剑 | K7: 物理 | L7: 敏捷 | M7: 力量 | N7: 781 | O7: 46 | P7: 0 | Q7: 20.86366505365031 | R7: 21.34020618556695 | S7: 14.690721649484551 | T7: 16.2371134020618 | U7: 5.0% | V7: 50.0% | W7: 3 | X7: 0.14 | Y7: 1.01275510204082 | Z7: 1.02551020408163 | AA7: 0 | AB7: 【最后的苏醒】战技构成序列消耗源石结晶时，返还50点技力。 | AC7: 【权能映射】天赋本质瓦解效果加强：自身获得攻击力提升时，其他友方干员获得一半的攻击力提升效果。 | AD7: 【？？？】？？？ | AE7: 【？？？】？？？ | AF7: 【？？？】？？？ | AG7: 无 | AH7: 无 | AI7: 无 | AJ7: 无 | AK7: 1 | AL7: 无 | AM7: 无 | AN7: 无 | AO7: 无 | AP7: 1 | AQ7: 无 | AR7: 无 | AS7: 无 | AT7: 无 | AV7: 7
A8: chr_0002_endminm_7 | B8: chr_0002_endminm | C8: 管理员(男) | D8: 7 | E8: Endministrator | F8: 近卫 | G8: ENDFIELD INDUSTRIES | H8: 猛击, 控制 | I8: 6★ | J8: 单手剑 | K8: 物理 | L8: 敏捷 | M8: 力量 | N8: 837 | O8: 49 | P8: 0 | Q8: 22.087944456132952 | R8: 22.762886597938078 | S8: 15.670103092783524 | T8: 17.31958762886592 | U8: 5.0% | V8: 50.0% | W8: 3 | X8: 0.14 | Y8: 1.01530612244898 | Z8: 1.03061224489796 | AA8: 0 | AB8: 【最后的苏醒】战技构成序列消耗源石结晶时，返还50点技力。 | AC8: 【权能映射】天赋本质瓦解效果加强：自身获得攻击力提升时，其他友方干员获得一半的攻击力提升效果。 | AD8: 【？？？】？？？ | AE8: 【？？？】？？？ | AF8: 【？？？】？？？ | AG8: 无 | AH8: 无 | AI8: 无 | AJ8: 无 | AK8: 1 | AL8: 无 | AM8: 无 | AN8: 无 | AO8: 无 | AP8: 1 | AQ8: 无 | AR8: 无 | AS8: 无 | AT8: 无 | AV8: 8
A9: chr_0002_endminm_8 | B9: chr_0002_endminm | C9: 管理员(男) | D9: 8 | E9: Endministrator | F9: 近卫 | G9: ENDFIELD INDUSTRIES | H9: 猛击, 控制 | I9: 6★ | J9: 单手剑 | K9: 物理 | L9: 敏捷 | M9: 力量 | N9: 893 | O9: 53 | P9: 0 | Q9: 23.312223858615592 | R9: 24.185567010309207 | S9: 16.649484536082497 | T9: 18.40206185567004 | U9: 5.0% | V9: 50.0% | W9: 3 | X9: 0.14 | Y9: 1.01785714285714 | Z9: 1.03571428571429 | AA9: 0 | AB9: 【最后的苏醒】战技构成序列消耗源石结晶时，返还50点技力。 | AC9: 【权能映射】天赋本质瓦解效果加强：自身获得攻击力提升时，其他友方干员获得一半的攻击力提升效果。 | AD9: 【？？？】？？？ | AE9: 【？？？】？？？ | AF9: 【？？？】？？？ | AG9: 无 | AH9: 无 | AI9: 无 | AJ9: 无 | AK9: 1 | AL9: 无 | AM9: 无 | AN9: 无 | AO9: 无 | AP9: 1 | AQ9: 无 | AR9: 无 | AS9: 无 | AT9: 无 | AV9: 9
A10: chr_0002_endminm_9 | B10: chr_0002_endminm | C10: 管理员(男) | D10: 9 | E10: Endministrator | F10: 近卫 | G10: ENDFIELD INDUSTRIES | H10: 猛击, 控制 | I10: 6★ | J10: 单手剑 | K10: 物理 | L10: 敏捷 | M10: 力量 | N10: 949 | O10: 56 | P10: 0 | Q10: 24.536503261098233 | R10: 25.608247422680336 | S10: 17.62886597938147 | T10: 19.484536082474165 | U10: 5.0% | V10: 50.0% | W10: 3 | X10: 0.14 | Y10: 1.02040816326531 | Z10: 1.04081632653061 | AA10: 0 | AB10: 【最后的苏醒】战技构成序列消耗源石结晶时，返还50点技力。 | AC10: 【权能映射】天赋本质瓦解效果加强：自身获得攻击力提升时，其他友方干员获得一半的攻击力提升效果。 | AD10: 【？？？】？？？ | AE10: 【？？？】？？？ | AF10: 【？？？】？？？ | AG10: 无 | AH10: 无 | AI10: 无 | AJ10: 无 | AK10: 1 | AL10: 无 | AM10: 无 | AN10: 无 | AO10: 无 | AP10: 1 | AQ10: 无 | AR10: 无 | AS10: 无 | AT10: 无 | AV10: 10
A11: chr_0002_endminm_10 | B11: chr_0002_endminm | C11: 管理员(男) | D11: 10 | E11: Endministrator | F11: 近卫 | G11: ENDFIELD INDUSTRIES | H11: 猛击, 控制 | I11: 6★ | J11: 单手剑 | K11: 物理 | L11: 敏捷 | M11: 力量 | N11: 1005 | O11: 59 | P11: 0 | Q11: 25.760782663580876 | R11: 27.030927835051465 | S11: 18.608247422680442 | T11: 20.56701030927828 | U11: 5.0% | V11: 50.0% | W11: 3 | X11: 0.14 | Y11: 1.02295918367347 | Z11: 1.04591836734694 | AA11: 0 | AB11: 【最后的苏醒】战技构成序列消耗源石结晶时，返还50点技力。 | AC11: 【权能映射】天赋本质瓦解效果加强：自身获得攻击力提升时，其他友方干员获得一半的攻击力提升效果。 | AD11: 【？？？】？？？ | AE11: 【？？？】？？？ | AF11: 【？？？】？？？ | AG11: 无 | AH11: 无 | AI11: 无 | AJ11: 无 | AK11: 1 | AL11: 无 | AM11: 无 | AN11: 无 | AO11: 无 | AP11: 1 | AQ11: 无 | AR11: 无 | AS11: 无 | AT11: 无 | AV11: 11
A12: chr_0002_endminm_11 | B12: chr_0002_endminm | C12: 管理员(男) | D12: 11 | E12: Endministrator | F12: 近卫 | G12: ENDFIELD INDUSTRIES | H12: 猛击, 控制 | I12: 6★ | J12: 单手剑 | K12: 物理 | L12: 敏捷 | M12: 力量 | N12: 1061 | O12: 62 | P12: 0 | Q12: 26.98506206606352 | R12: 28.453608247422597 | S12: 19.587628865979415 | T12: 21.649484536082404 | U12: 5.0% | V12: 50.0% | W12: 3 | X12: 0.14 | Y12: 1.02551020408163 | Z12: 1.05102040816327 | AA12: 0 | AB12: 【最后的苏醒】战技构成序列消耗源石结晶时，返还50点技力。 | AC12: 【权能映射】天赋本质瓦解效果加强：自身获得攻击力提升时，其他友方干员获得一半的攻击力提升效果。 | AD12: 【？？？】？？？ | AE12: 【？？？】？？？ | AF12: 【？？？】？？？ | AG12: 无 | AH12: 无 | AI12: 无 | AJ12: 无 | AK12: 1 | AL12: 无 | AM12: 无 | AN12: 无 | AO12: 无 | AP12: 1 | AQ12: 无 | AR12: 无 | AS12: 无 | AT12: 无 | AV12: 12
A13: chr_0002_endminm_12 | B13: chr_0002_endminm | C13: 管理员(男) | D13: 12 | E13: Endministrator | F13: 近卫 | G13: ENDFIELD INDUSTRIES | H13: 猛击, 控制 | I13: 6★ | J13: 单手剑 | K13: 物理 | L13: 敏捷 | M13: 力量 | N13: 1117 | O13: 66 | P13: 0 | Q13: 28.20934146854616 | R13: 29.876288659793726 | S13: 20.567010309278388 | T13: 22.731958762886524 | U13: 5.0% | V13: 50.0% | W13: 3 | X13: 0.14 | Y13: 1.0280612244898 | Z13: 1.05612244897959 | AA13: 0 | AB13: 【最后的苏醒】战技构成序列消耗源石结晶时，返还50点技力。 | AC13: 【权能映射】天赋本质瓦解效果加强：自身获得攻击力提升时，其他友方干员获得一半的攻击力提升效果。 | AD13: 【？？？】？？？ | AE13: 【？？？】？？？ | AF13: 【？？？】？？？ | AG13: 无 | AH13: 无 | AI13: 无 | AJ13: 无 | AK13: 1 | AL13: 无 | AM13: 无 | AN13: 无 | AO13: 无 | AP13: 1 | AQ13: 无 | AR13: 无 | AS13: 无 | AT13: 无 | AV13: 13
... A99: chr_0002_endminm_94 | B99: chr_0002_endminm | C99: 管理员(男) | D99: 94 | E99: Endministrator | F99: 近卫 | G99: ENDFIELD INDUSTRIES | H99: 猛击, 控制 | I99: 6★ | J99: 单手剑 | K99: 物理 | L99: 敏捷 | M99: 力量 | N99: 5719 | O99: 332 | P99: 0 | Q99: 128.60025247212278 | R99: 146.53608247422636 | S99: 100.87628865979413 | T99: 111.4948453608244 | U99: 5.0% | V99: 50.0% | W99: 3 | X99: 0.14 | Y99: 1.23724489795918 | Z99: 1.47448979591837 | AA99: 4 | AB99: 【最后的苏醒】战技构成序列消耗源石结晶时，返还50点技力。 | AC99: 【权能映射】天赋本质瓦解效果加强：自身获得攻击力提升时，其他友方干员获得一半的攻击力提升效果。 | AD99: 【？？？】？？？ | AE99: 【？？？】？？？ | AF99: 【？？？】？？？ | AG99: 【游刃】干员敏捷能力值提升10。 | AH99: 【游刃】干员敏捷能力值提升15。 | AI99: 【游刃】干员敏捷能力值提升15。 | AJ99: 【游刃】干员敏捷能力值提升20。 | AK99: 1 | AL99: 【本质瓦解 Lv.1】当敌人附着的源石结晶被消耗后，自身攻击力+15%，持续15秒，该效果无法叠加。 | AM99: 【本质瓦解 Lv.1】当敌人附着的源石结晶被消耗后，自身攻击力+15%，持续15秒，该效果无法叠加。 | AN99: 【本质瓦解 Lv.2】当敌人附着的源石结晶被消耗后，自身攻击力+30%，持续15秒，该效果无法叠加。 | AO99: 无 | AP99: 1 | AQ99: 【现实静滞 Lv.1】附着源石结晶的敌人受到的物理伤害+10%。 | AR99: 【现实静滞 Lv.1】附着源石结晶的敌人受到的物理伤害+10%。 | AS99: 【现实静滞 Lv.2】附着源石结晶的敌人受到的物理伤害+20%。 | AT99: 无 | AV99: 99
A100: chr_0002_endminm_95 | B100: chr_0002_endminm | C100: 管理员(男) | D100: 95 | E100: Endministrator | F100: 近卫 | G100: ENDFIELD INDUSTRIES | H100: 猛击, 控制 | I100: 6★ | J100: 单手剑 | K100: 物理 | L100: 敏捷 | M100: 力量 | N100: 5776 | O100: 335 | P100: 0 | Q100: 129.82453187460544 | R100: 147.9587628865975 | S100: 101.8556701030931 | T100: 112.57731958762851 | U100: 5.0% | V100: 50.0% | W100: 3 | X100: 0.14 | Y100: 1.23979591836735 | Z100: 1.47959183673469 | AA100: 4 | AB100: 【最后的苏醒】战技构成序列消耗源石结晶时，返还50点技力。 | AC100: 【权能映射】天赋本质瓦解效果加强：自身获得攻击力提升时，其他友方干员获得一半的攻击力提升效果。 | AD100: 【？？？】？？？ | AE100: 【？？？】？？？ | AF100: 【？？？】？？？ | AG100: 【游刃】干员敏捷能力值提升10。 | AH100: 【游刃】干员敏捷能力值提升15。 | AI100: 【游刃】干员敏捷能力值提升15。 | AJ100: 【游刃】干员敏捷能力值提升20。 | AK100: 1 | AL100: 【本质瓦解 Lv.1】当敌人附着的源石结晶被消耗后，自身攻击力+15%，持续15秒，该效果无法叠加。 | AM100: 【本质瓦解 Lv.1】当敌人附着的源石结晶被消耗后，自身攻击力+15%，持续15秒，该效果无法叠加。 | AN100: 【本质瓦解 Lv.2】当敌人附着的源石结晶被消耗后，自身攻击力+30%，持续15秒，该效果无法叠加。 | AO100: 无 | AP100: 1 | AQ100: 【现实静滞 Lv.1】附着源石结晶的敌人受到的物理伤害+10%。 | AR100: 【现实静滞 Lv.1】附着源石结晶的敌人受到的物理伤害+10%。 | AS100: 【现实静滞 Lv.2】附着源石结晶的敌人受到的物理伤害+20%。 | AT100: 无
A101: chr_0002_endminm_96 | B101: chr_0002_endminm | C101: 管理员(男) | D101: 96 | E101: Endministrator | F101: 近卫 | G101: ENDFIELD INDUSTRIES | H101: 猛击, 控制 | I101: 6★ | J101: 单手剑 | K101: 物理 | L101: 敏捷 | M101: 力量 | N101: 5832 | O101: 339 | P101: 0 | Q101: 131.04881127708808 | R101: 149.3814432989686 | S101: 102.83505154639208 | T101: 113.65979381443263 | U101: 5.0% | V101: 50.0% | W101: 3 | X101: 0.14 | Y101: 1.24234693877551 | Z101: 1.48469387755102 | AA101: 4 | AB101: 【最后的苏醒】战技构成序列消耗源石结晶时，返还50点技力。 | AC101: 【权能映射】天赋本质瓦解效果加强：自身获得攻击力提升时，其他友方干员获得一半的攻击力提升效果。 | AD101: 【？？？】？？？ | AE101: 【？？？】？？？ | AF101: 【？？？】？？？ | AG101: 【游刃】干员敏捷能力值提升10。 | AH101: 【游刃】干员敏捷能力值提升15。 | AI101: 【游刃】干员敏捷能力值提升15。 | AJ101: 【游刃】干员敏捷能力值提升20。 | AK101: 1 | AL101: 【本质瓦解 Lv.1】当敌人附着的源石结晶被消耗后，自身攻击力+15%，持续15秒，该效果无法叠加。 | AM101: 【本质瓦解 Lv.1】当敌人附着的源石结晶被消耗后，自身攻击力+15%，持续15秒，该效果无法叠加。 | AN101: 【本质瓦解 Lv.2】当敌人附着的源石结晶被消耗后，自身攻击力+30%，持续15秒，该效果无法叠加。 | AO101: 无 | AP101: 1 | AQ101: 【现实静滞 Lv.1】附着源石结晶的敌人受到的物理伤害+10%。 | AR101: 【现实静滞 Lv.1】附着源石结晶的敌人受到的物理伤害+10%。 | AS101: 【现实静滞 Lv.2】附着源石结晶的敌人受到的物理伤害+20%。 | AT101: 无
A102: chr_0002_endminm_97 | B102: chr_0002_endminm | C102: 管理员(男) | D102: 97 | E102: Endministrator | F102: 近卫 | G102: ENDFIELD INDUSTRIES | H102: 猛击, 控制 | I102: 6★ | J102: 单手剑 | K102: 物理 | L102: 敏捷 | M102: 力量 | N102: 5888 | O102: 342 | P102: 0 | Q102: 132.2730906795707 | R102: 150.80412371133974 | S102: 103.81443298969104 | T102: 114.74226804123676 | U102: 5.0% | V102: 50.0% | W102: 3 | X102: 0.14 | Y102: 1.24489795918367 | Z102: 1.48979591836735 | AA102: 4 | AB102: 【最后的苏醒】战技构成序列消耗源石结晶时，返还50点技力。 | AC102: 【权能映射】天赋本质瓦解效果加强：自身获得攻击力提升时，其他友方干员获得一半的攻击力提升效果。 | AD102: 【？？？】？？？ | AE102: 【？？？】？？？ | AF102: 【？？？】？？？ | AG102: 【游刃】干员敏捷能力值提升10。 | AH102: 【游刃】干员敏捷能力值提升15。 | AI102: 【游刃】干员敏捷能力值提升15。 | AJ102: 【游刃】干员敏捷能力值提升20。 | AK102: 1 | AL102: 【本质瓦解 Lv.1】当敌人附着的源石结晶被消耗后，自身攻击力+15%，持续15秒，该效果无法叠加。 | AM102: 【本质瓦解 Lv.1】当敌人附着的源石结晶被消耗后，自身攻击力+15%，持续15秒，该效果无法叠加。 | AN102: 【本质瓦解 Lv.2】当敌人附着的源石结晶被消耗后，自身攻击力+30%，持续15秒，该效果无法叠加。 | AO102: 无 | AP102: 1 | AQ102: 【现实静滞 Lv.1】附着源石结晶的敌人受到的物理伤害+10%。 | AR102: 【现实静滞 Lv.1】附着源石结晶的敌人受到的物理伤害+10%。 | AS102: 【现实静滞 Lv.2】附着源石结晶的敌人受到的物理伤害+20%。 | AT102: 无
A103: chr_0002_endminm_98 | B103: chr_0002_endminm | C103: 管理员(男) | D103: 98 | E103: Endministrator | F103: 近卫 | G103: ENDFIELD INDUSTRIES | H103: 猛击, 控制 | I103: 6★ | J103: 单手剑 | K103: 物理 | L103: 敏捷 | M103: 力量 | N103: 5944 | O103: 345 | P103: 0 | Q103: 133.49737008205335 | R103: 152.22680412371088 | S103: 104.79381443299002 | T103: 115.82474226804088 | U103: 5.0% | V103: 50.0% | W103: 3 | X103: 0.14 | Y103: 1.24744897959184 | Z103: 1.49489795918367 | AA103: 4 | AB103: 【最后的苏醒】战技构成序列消耗源石结晶时，返还50点技力。 | AC103: 【权能映射】天赋本质瓦解效果加强：自身获得攻击力提升时，其他友方干员获得一半的攻击力提升效果。 | AD103: 【？？？】？？？ | AE103: 【？？？】？？？ | AF103: 【？？？】？？？ | AG103: 【游刃】干员敏捷能力值提升10。 | AH103: 【游刃】干员敏捷能力值提升15。 | AI103: 【游刃】干员敏捷能力值提升15。 | AJ103: 【游刃】干员敏捷能力值提升20。 | AK103: 1 | AL103: 【本质瓦解 Lv.1】当敌人附着的源石结晶被消耗后，自身攻击力+15%，持续15秒，该效果无法叠加。 | AM103: 【本质瓦解 Lv.1】当敌人附着的源石结晶被消耗后，自身攻击力+15%，持续15秒，该效果无法叠加。 | AN103: 【本质瓦解 Lv.2】当敌人附着的源石结晶被消耗后，自身攻击力+30%，持续15秒，该效果无法叠加。 | AO103: 无 | AP103: 1 | AQ103: 【现实静滞 Lv.1】附着源石结晶的敌人受到的物理伤害+10%。 | AR103: 【现实静滞 Lv.1】附着源石结晶的敌人受到的物理伤害+10%。 | AS103: 【现实静滞 Lv.2】附着源石结晶的敌人受到的物理伤害+20%。 | AT103: 无
A104: chr_0002_endminm_99 | B104: chr_0002_endminm | C104: 管理员(男) | D104: 99 | E104: Endministrator | F104: 近卫 | G104: ENDFIELD INDUSTRIES | H104: 猛击, 控制 | I104: 6★ | J104: 单手剑 | K104: 物理 | L104: 敏捷 | M104: 力量 | N104: 6000 | O104: 348 | P104: 0 | Q104: 134.721649484536 | R104: 153.649484536082 | S104: 105.773195876289 | T104: 116.907216494845 | U104: 5.0% | V104: 50.0% | W104: 3 | X104: 0.14 | Y104: 1.25 | Z104: 1.5 | AA104: 4 | AB104: 【最后的苏醒】战技构成序列消耗源石结晶时，返还50点技力。 | AC104: 【权能映射】天赋本质瓦解效果加强：自身获得攻击力提升时，其他友方干员获得一半的攻击力提升效果。 | AD104: 【？？？】？？？ | AE104: 【？？？】？？？ | AF104: 【？？？】？？？ | AG104: 【游刃】干员敏捷能力值提升10。 | AH104: 【游刃】干员敏捷能力值提升15。 | AI104: 【游刃】干员敏捷能力值提升15。 | AJ104: 【游刃】干员敏捷能力值提升20。 | AK104: 1 | AL104: 【本质瓦解 Lv.1】当敌人附着的源石结晶被消耗后，自身攻击力+15%，持续15秒，该效果无法叠加。 | AM104: 【本质瓦解 Lv.1】当敌人附着的源石结晶被消耗后，自身攻击力+15%，持续15秒，该效果无法叠加。 | AN104: 【本质瓦解 Lv.2】当敌人附着的源石结晶被消耗后，自身攻击力+30%，持续15秒，该效果无法叠加。 | AO104: 无 | AP104: 1 | AQ104: 【现实静滞 Lv.1】附着源石结晶的敌人受到的物理伤害+10%。 | AR104: 【现实静滞 Lv.1】附着源石结晶的敌人受到的物理伤害+10%。 | AS104: 【现实静滞 Lv.2】附着源石结晶的敌人受到的物理伤害+20%。 | AT104: 无
A105: chr_0020_meurs_1 | B105: chr_0020_meurs | C105: 卡契尔 | D105: 1 | E105: Catcher | F105: 重装 | G105: ENDFIELD INDUSTRIES | H105: 庇护, 护盾, 虚弱 | I105: 4★ | J105: 双手剑 | K105: 物理 | L105: 力量 | M105: 意志 | N105: 500 | O105: 30 | P105: 0 | Q105: 21.6494845360825 | R105: 9.79381443298969 | S105: 8.76288659793815 | T105: 11.4536082474227 | U105: 5.0% | V105: 50.0% | W105: 3 | X105: 0.0958125 | Y105: 1.0 | Z105: 1.0 | AA105: 0 | AB105: 【多重战备】战技刚性阻击和终结技教科书式猛攻命中敌人后，额外造成一次[300+防御力×5.0]的物理伤害。 | AC105: 【额外特训】防御力+20，意志+10。 | AD105: 【不屈心锚】连携技即时压制提供的护盾持续时间+5秒。 | AE105: 【苦难代偿】终结技教科书式猛攻所需的终结技能量-10%。 | AF105: 【无悔抉择】卡契尔存在护盾时，战技刚性阻击成功命中敌人后返还10点技力。 | AG105: 无 | AH105: 无 | AI105: 无 | AJ105: 无 | AK105: 1 | AL105: 无 | AM105: 无 | AN105: 无 | AO105: 无 | AP105: 1 | AQ105: 无 | AR105: 无 | AS105: 无 | AT105: 无
A106: chr_0020_meurs_2 | B106: chr_0020_meurs | C106: 卡契尔 | D106: 2 | E106: Catcher | F106: 重装 | G106: ENDFIELD INDUSTRIES | H106: 庇护, 护盾, 虚弱 | I106: 4★ | J106: 双手剑 | K106: 物理 | L106: 力量 | M106: 意志 | N106: 556 | O106: 33 | P106: 0 | Q106: 23.388386282348016 | R106: 10.773195876288662 | S106: 9.639175257731965 | T106: 12.523984851672653 | U106: 5.0% | V106: 50.0% | W106: 3 | X106: 0.0958125 | Y106: 1.00255102040816 | Z106: 1.00510204081633 | AA106: 0 | AB106: 【多重战备】战技刚性阻击和终结技教科书式猛攻命中敌人后，额外造成一次[300+防御力×5.0]的物理伤害。 | AC106: 【额外特训】防御力+20，意志+10。 | AD106: 【不屈心锚】连携技即时压制提供的护盾持续时间+5秒。 | AE106: 【苦难代偿】终结技教科书式猛攻所需的终结技能量-10%。 | AF106: 【无悔抉择】卡契尔存在护盾时，战技刚性阻击成功命中敌人后返还10点技力。 | AG106: 无 | AH106: 无 | AI106: 无 | AJ106: 无 | AK106: 1 | AL106: 无 | AM106: 无 | AN106: 无 | AO106: 无 | AP106: 1 | AQ106: 无 | AR106: 无 | AS106: 无 | AT106: 无
A107: chr_0020_meurs_3 | B107: chr_0020_meurs | C107: 卡契尔 | D107: 3 | E107: Catcher | F107: 重装 | G107: ENDFIELD INDUSTRIES | H107: 庇护, 护盾, 虚弱 | I107: 4★ | J107: 双手剑 | K107: 物理 | L107: 力量 | M107: 意志 | N107: 612 | O107: 36 | P107: 0 | Q107: 25.12728802861353 | R107: 11.752577319587635 | S107: 10.51546391752578 | T107: 13.594361455922604 | U107: 5.0% | V107: 50.0% | W107: 3 | X107: 0.0958125 | Y107: 1.00510204081633 | Z107: 1.01020408163265 | AA107: 0 | AB107: 【多重战备】战技刚性阻击和终结技教科书式猛攻命中敌人后，额外造成一次[300+防御力×5.0]的物理伤害。 | AC107: 【额外特训】防御力+20，意志+10。 | AD107: 【不屈心锚】连携技即时压制提供的护盾持续时间+5秒。 | AE107: 【苦难代偿】终结技教科书式猛攻所需的终结技能量-10%。 | AF107: 【无悔抉择】卡契尔存在护盾时，战技刚性阻击成功命中敌人后返还10点技力。 | AG107: 无 | AH107: 无 | AI107: 无 | AJ107: 无 | AK107: 1 | AL107: 无 | AM107: 无 | AN107: 无 | AO107: 无 | AP107: 1 | AQ107: 无 | AR107: 无 | AS107: 无 | AT107: 无
A108: chr_0020_meurs_4 | B108: chr_0020_meurs | C108: 卡契尔 | D108: 4 | E108: Catcher | F108: 重装 | G108: ENDFIELD INDUSTRIES | H108: 庇护, 护盾, 虚弱 | I108: 4★ | J108: 双手剑 | K108: 物理 | L108: 力量 | M108: 意志 | N108: 668 | O108: 39 | P108: 0 | Q108: 26.866189774879047 | R108: 12.731958762886606 | S108: 11.391752577319595 | T108: 14.664738060172557 | U108: 5.0% | V108: 50.0% | W108: 3 | X108: 0.0958125 | Y108: 1.00765306122449 | Z108: 1.01530612244898 | AA108: 0 | AB108: 【多重战备】战技刚性阻击和终结技教科书式猛攻命中敌人后，额外造成一次[300+防御力×5.0]的物理伤害。 | AC108: 【额外特训】防御力+20，意志+10。 | AD108: 【不屈心锚】连携技即时压制提供的护盾持续时间+5秒。 | AE108: 【苦难代偿】终结技教科书式猛攻所需的终结技能量-10%。 | AF108: 【无悔抉择】卡契尔存在护盾时，战技刚性阻击成功命中敌人后返还10点技力。 | AG108: 无 | AH108: 无 | AI108: 无 | AJ108: 无 | AK108: 1 | AL108: 无 | AM108: 无 | AN108: 无 | AO108: 无 | AP108: 1 | AQ108: 无 | AR108: 无 | AS108: 无 | AT108: 无
A109: chr_0020_meurs_5 | B109: chr_0020_meurs | C109: 卡契尔 | D109: 5 | E109: Catcher | F109: 重装 | G109: ENDFIELD INDUSTRIES | H109: 庇护, 护盾, 虚弱 | I109: 4★ | J109: 双手剑 | K109: 物理 | L109: 力量 | M109: 意志 | N109: 724 | O109: 42 | P109: 0 | Q109: 28.605091521144562 | R109: 13.711340206185579 | S109: 12.26804123711341 | T109: 15.735114664422508 | U109: 5.0% | V109: 50.0% | W109: 3 | X109: 0.0958125 | Y109: 1.01020408163265 | Z109: 1.02040816326531 | AA109: 0 | AB109: 【多重战备】战技刚性阻击和终结技教科书式猛攻命中敌人后，额外造成一次[300+防御力×5.0]的物理伤害。 | AC109: 【额外特训】防御力+20，意志+10。 | AD109: 【不屈心锚】连携技即时压制提供的护盾持续时间+5秒。 | AE109: 【苦难代偿】终结技教科书式猛攻所需的终结技能量-10%。 | AF109: 【无悔抉择】卡契尔存在护盾时，战技刚性阻击成功命中敌人后返还10点技力。 | AG109: 无 | AH109: 无 | AI109: 无 | AJ109: 无 | AK109: 1 | AL109: 无 | AM109: 无 | AN109: 无 | AO109: 无 | AP109: 1 | AQ109: 无 | AR109: 无 | AS109: 无 | AT109: 无
A110: chr_0020_meurs_6 | B110: chr_0020_meurs | C110: 卡契尔 | D110: 6 | E110: Catcher | F110: 重装 | G110: ENDFIELD INDUSTRIES | H110: 庇护, 护盾, 虚弱 | I110: 4★ | J110: 双手剑 | K110: 物理 | L110: 力量 | M110: 意志 | N110: 781 | O110: 45 | P110: 0 | Q110: 30.343993267410077 | R110: 14.690721649484551 | S110: 13.144329896907225 | T110: 16.805491268672462 | U110: 5.0% | V110: 50.0% | W110: 3 | X110: 0.0958125 | Y110: 1.01275510204082 | Z110: 1.02551020408163 | AA110: 0 | AB110: 【多重战备】战技刚性阻击和终结技教科书式猛攻命中敌人后，额外造成一次[300+防御力×5.0]的物理伤害。 | AC110: 【额外特训】防御力+20，意志+10。 | AD110: 【不屈心锚】连携技即时压制提供的护盾持续时间+5秒。 | AE110: 【苦难代偿】终结技教科书式猛攻所需的终结技能量-10%。 | AF110: 【无悔抉择】卡契尔存在护盾时，战技刚性阻击成功命中敌人后返还10点技力。 | AG110: 无 | AH110: 无 | AI110: 无 | AJ110: 无 | AK110: 1 | AL110: 无 | AM110: 无 | AN110: 无 | AO110: 无 | AP110: 1 | AQ110: 无 | AR110: 无 | AS110: 无 | AT110: 无
A111: chr_0020_meurs_7 | B111: chr_0020_meurs | C111: 卡契尔 | D111: 7 | E111: Catcher | F111: 重装 | G111: ENDFIELD INDUSTRIES | H111: 庇护, 护盾, 虚弱 | I111: 4★ | J111: 双手剑 | K111: 物理 | L111: 力量 | M111: 意志 | N111: 837 | O111: 48 | P111: 0 | Q111: 32.082895013675596 | R111: 15.670103092783524 | S111: 14.02061855670104 | T111: 17.875867872922413 | U111: 5.0% | V111: 50.0% | W111: 3 | X111: 0.0958125 | Y111: 1.01530612244898 | Z111: 1.03061224489796 | AA111: 0 | AB111: 【多重战备】战技刚性阻击和终结技教科书式猛攻命中敌人后，额外造成一次[300+防御力×5.0]的物理伤害。 | AC111: 【额外特训】防御力+20，意志+10。 | AD111: 【不屈心锚】连携技即时压制提供的护盾持续时间+5秒。 | AE111: 【苦难代偿】终结技教科书式猛攻所需的终结技能量-10%。 | AF111: 【无悔抉择】卡契尔存在护盾时，战技刚性阻击成功命中敌人后返还10点技力。 | AG111: 无 | AH111: 无 | AI111: 无 | AJ111: 无 | AK111: 1 | AL111: 无 | AM111: 无 | AN111: 无 | AO111: 无 | AP111: 1 | AQ111: 无 | AR111: 无 | AS111: 无 | AT111: 无
... A2679: chr_0029_pograni_99 | B2679: chr_0029_pograni | C2679: 骏卫 | D2679: 99 | E2679: Pogranichnik | F2679: 先锋 | G2679: ENDFIELD INDUSTRIES | H2679: 技力恢复, 碎甲 | I2679: 6★ | J2679: 单手剑 | K2679: 物理 | L2679: 意志 | M2679: 敏捷 | N2679: 6000 | O2679: 350 | P2679: 0 | Q2679: 110.226804123711 | R2679: 120.024742268041 | S2679: 105.773195876289 | T2679: 188.721649484536 | U2679: 5.0% | V2679: 50.0% | W2679: 3 | X2679: 0.14 | Y2679: 1.25 | Z2679: 1.5 | AA2679: 4 | AB2679: 【阵线扫荡】战技粉碎阵线命中至少两个敌人时，返还15点技力。 | AC2679: 【“行军”】意志+20，造成的物理伤害+10%。 | AD2679: 【战旗飘扬时】天赋活着的旗帜效果加强：获得士气激昂所需的技力恢复量降低至60点。自身士气激昂最大叠加层数+2。 | AE2679: 【塔卫二之盾】终结技盾卫旗队，上前所需的终结技能量-15%。 | AF2679: 【新铸剑锋】连携技盈月邀击冷却时间-2秒，且技力恢复量变为原本的1.2倍。 | AG2679: 【守誓】干员意志能力值提升10。 | AH2679: 【守誓】干员意志能力值提升15。 | AI2679: 【守誓】干员意志能力值提升15。 | AJ2679: 【守誓】干员意志能力值提升20。 | AK2679: 1 | AL2679: 【战术教导 Lv.2】当任意干员触发终结技盾卫旗队，上前的后续效果后，也会获得持续10秒的士气激昂。需要激活天赋活着的旗帜。 | AM2679: 【战术教导 Lv.1】当任意干员触发终结技盾卫旗队，上前的后续效果后，也会获得持续5秒的士气激昂。需要激活天赋活着的旗帜。 | AN2679: 【战术教导 Lv.2】当任意干员触发终结技盾卫旗队，上前的后续效果后，也会获得持续10秒的士气激昂。需要激活天赋活着的旗帜。 | AO2679: 无 | AP2679: 1 | AQ2679: 【活着的旗帜 Lv.1】战斗中，通过自身技能每恢复80点技力后，获得持续20秒的士气激昂。士气激昂效果：攻击力+4%，源石技艺强度+4。该效果最多叠加3层，每层单独计算时间。 | AR2679: 【活着的旗帜 Lv.1】战斗中，通过自身技能每恢复80点技力后，获得持续20秒的士气激昂。士气激昂效果：攻击力+4%，源石技艺强度+4。该效果最多叠加3层，每层单独计算时间。 | AS2679: 【活着的旗帜 Lv.2】战斗中，通过自身技能每恢复80点技力后，获得持续20秒的士气激昂。士气激昂效果：攻击力+8%，源石技艺强度+8。该效果最多叠加3层，每层单独计算时间。 | AT2679: 无

Sheet 终末地干员数据
A1: 干员ID | B1: 干员名称 | C1: 等级 | D1: 英文名 | E1: 职业 | F1: 阵营 | G1: 标签 | H1: 稀有度 | I1: 武器类型 | J1: 干员属性 | K1: 主属性 | L1: 副属性 | M1: 生命值 | N1: 攻击力 | O1: 防御力 | P1: 力量 | Q1: 敏捷 | R1: 智识 | S1: 意志 | T1: 暴击率 | U1: 暴击伤害 | V1: 普通攻击范围 | W1: 韧性削减系数 | X1: 物理等级系数 | Y1: 法术等级系数 | Z1: 精英化等阶 | AA1: 潜能天赋① | AB1: 潜能天赋② | AC1: 潜能天赋③ | AD1: 潜能天赋④ | AE1: 潜能天赋⑤ | AF1: 信赖天赋节点① | AG1: 信赖天赋节点② | AH1: 信赖天赋节点③ | AI1: 信赖天赋节点④ | AJ1: 技能天赋节点①等级 | AK1: 技能天赋节点①效果 | AL1: 技能天赋节点②等级 | AM1: 技能天赋节点②效果
A2: chr_9000_endmin | B2: =VLOOKUP("chr_9000_endmin_90", DataSource!$A:$P, 3, FALSE) -> 管理员 | C2: 90 | D2: =VLOOKUP($A2&"_"&$C2, DataSource!$A:$AT, 5, FALSE) -> Endministrator | E2: =VLOOKUP($A2&"_"&$C2, DataSource!$A:$AT, 6, FALSE) -> 近卫 | F2: =VLOOKUP($A2&"_"&$C2, DataSource!$A:$AT, 7, FALSE) -> ENDFIELD INDUSTRIES | G2: =VLOOKUP($A2&"_"&$C2, DataSource!$A:$AT, 8, FALSE) -> 猛击, 控制 | H2: =VLOOKUP($A2&"_"&$C2, DataSource!$A:$AT, 9, FALSE) -> 6★ | I2: =VLOOKUP($A2&"_"&$C2, DataSource!$A:$AT, 10, FALSE) -> 单手剑 | J2: =VLOOKUP($A2&"_"&$C2, DataSource!$A:$AT, 11, FALSE) -> 物理 | K2: =VLOOKUP($A2&"_"&$C2, DataSource!$A:$AT, 12, FALSE) -> 敏捷 | L2: =VLOOKUP($A2&"_"&$C2, DataSource!$A:$AT, 13, FALSE) -> 力量 | M2: =VLOOKUP($A2&"_"&$C2, DataSource!$A:$AT, 14, FALSE) -> 5495 | N2: =VLOOKUP($A2&"_"&$C2, DataSource!$A:$AT, 15, FALSE) -> 319 | O2: =VLOOKUP($A2&"_"&$C2, DataSource!$A:$AT, 16, FALSE) -> 0 | P2: =VLOOKUP($A2&"_"&$C2, DataSource!$A:$AT, 17, FALSE) -> 123.70313486219221 | Q2: =VLOOKUP($A2&"_"&$C2, DataSource!$A:$AT, 18, FALSE) -> 140.84536082474185 | R2: =VLOOKUP($A2&"_"&$C2, DataSource!$A:$AT, 19, FALSE) -> 96.95876288659824 | S2: =VLOOKUP($A2&"_"&$C2, DataSource!$A:$AT, 20, FALSE) -> 107.16494845360792 | T2: =VLOOKUP($A2&"_"&$C2, DataSource!$A:$AT, 21, FALSE) -> 5.0% | U2: =VLOOKUP($A2&"_"&$C2, DataSource!$A:$AT, 22, FALSE) -> 50.0% | V2: =VLOOKUP($A2&"_"&$C2, DataSource!$A:$AT, 23, FALSE) -> 3 | W2: =VLOOKUP($A2&"_"&$C2, DataSource!$A:$AT, 24, FALSE) -> 0.14 | X2: =VLOOKUP($A2&"_"&$C2, DataSource!$A:$AT, 25, FALSE) -> 1.22704081632653 | Y2: =VLOOKUP($A2&"_"&$C2, DataSource!$A:$AT, 26, FALSE) -> 1.45408163265306 | Z2: =VLOOKUP($A2&"_"&$C2, DataSource!$A:$AT, 27, FALSE) -> 4 | AA2: =VLOOKUP($A2&"_"&$C2, DataSource!$A:$AT, 28, FALSE) -> 【最后的苏醒】战技构成序列消耗源石结晶时，返还50点技力。 | AB2: =VLOOKUP($A2&"_"&$C2, DataSource!$A:$AT, 29, FALSE) -> 【权能映射】天赋本质瓦解效果加强：自身获得攻击力提升时，其他友方干员获得一半的攻击力提升效果。 | AC2: =VLOOKUP($A2&"_"&$C2, DataSource!$A:$AT, 30, FALSE) -> 【？？？】？？？ | AD2: =VLOOKUP($A2&"_"&$C2, DataSource!$A:$AT, 31, FALSE) -> 【？？？】？？？ | AE2: =VLOOKUP($A2&"_"&$C2, DataSource!$A:$AT, 32, FALSE) -> 【？？？】？？？ | AF2: =VLOOKUP($A2&"_"&$C2, DataSource!$A:$AT, 33, FALSE) -> 【游刃】干员敏捷能力值提升10。 | AG2: =VLOOKUP($A2&"_"&$C2, DataSource!$A:$AT, 34, FALSE) -> 【游刃】干员敏捷能力值提升15。 | AH2: =VLOOKUP($A2&"_"&$C2, DataSource!$A:$AT, 35, FALSE) -> 【游刃】干员敏捷能力值提升15。 | AI2: =VLOOKUP($A2&"_"&$C2, DataSource!$A:$AT, 36, FALSE) -> 【游刃】干员敏捷能力值提升20。 | AJ2: 1 | AK2: =VLOOKUP($A2&"_"&$C2, DataSource!$A:$AT, 39 + AJ2 - 1, FALSE) -> 【本质瓦解 Lv.1】当敌人附着的源石结晶被消耗后，自身攻击力+15%，持续15秒，该效果无法叠加。 | AL2: 1 | AM2: =VLOOKUP($A2&"_"&$C2, DataSource!$A:$AT, 44 + AL2 - 1, FALSE) -> 【现实静滞 Lv.1】附着源石结晶的敌人受到的物理伤害+10%。
A3: chr_0002_endminm | B3: =VLOOKUP("chr_0002_endminm_90", DataSource!$A:$P, 3, FALSE) -> 管理员(男) | C3: 90 | D3: =VLOOKUP($A3&"_"&$C3, DataSource!$A:$AT, 5, FALSE) -> Endministrator | E3: =VLOOKUP($A3&"_"&$C3, DataSource!$A:$AT, 6, FALSE) -> 近卫 | F3: =VLOOKUP($A3&"_"&$C3, DataSource!$A:$AT, 7, FALSE) -> ENDFIELD INDUSTRIES | G3: =VLOOKUP($A3&"_"&$C3, DataSource!$A:$AT, 8, FALSE) -> 猛击, 控制 | H3: =VLOOKUP($A3&"_"&$C3, DataSource!$A:$AT, 9, FALSE) -> 6★ | I3: =VLOOKUP($A3&"_"&$C3, DataSource!$A:$AT, 10, FALSE) -> 单手剑 | J3: =VLOOKUP($A3&"_"&$C3, DataSource!$A:$AT, 11, FALSE) -> 物理 | K3: =VLOOKUP($A3&"_"&$C3, DataSource!$A:$AT, 12, FALSE) -> 敏捷 | L3: =VLOOKUP($A3&"_"&$C3, DataSource!$A:$AT, 13, FALSE) -> 力量 | M3: =VLOOKUP($A3&"_"&$C3, DataSource!$A:$AT, 14, FALSE) -> 5495 | N3: =VLOOKUP($A3&"_"&$C3, DataSource!$A:$AT, 15, FALSE) -> 319 | O3: =VLOOKUP($A3&"_"&$C3, DataSource!$A:$AT, 16, FALSE) -> 0 | P3: =VLOOKUP($A3&"_"&$C3, DataSource!$A:$AT, 17, FALSE) -> 123.70313486219221 | Q3: =VLOOKUP($A3&"_"&$C3, DataSource!$A:$AT, 18, FALSE) -> 140.84536082474185 | R3: =VLOOKUP($A3&"_"&$C3, DataSource!$A:$AT, 19, FALSE) -> 96.95876288659824 | S3: =VLOOKUP($A3&"_"&$C3, DataSource!$A:$AT, 20, FALSE) -> 107.16494845360792 | T3: =VLOOKUP($A3&"_"&$C3, DataSource!$A:$AT, 21, FALSE) -> 5.0% | U3: =VLOOKUP($A3&"_"&$C3, DataSource!$A:$AT, 22, FALSE) -> 50.0% | V3: =VLOOKUP($A3&"_"&$C3, DataSource!$A:$AT, 23, FALSE) -> 3 | W3: =VLOOKUP($A3&"_"&$C3, DataSource!$A:$AT, 24, FALSE) -> 0.14 | X3: =VLOOKUP($A3&"_"&$C3, DataSource!$A:$AT, 25, FALSE) -> 1.22704081632653 | Y3: =VLOOKUP($A3&"_"&$C3, DataSource!$A:$AT, 26, FALSE) -> 1.45408163265306 | Z3: =VLOOKUP($A3&"_"&$C3, DataSource!$A:$AT, 27, FALSE) -> 4 | AA3: =VLOOKUP($A3&"_"&$C3, DataSource!$A:$AT, 28, FALSE) -> 【最后的苏醒】战技构成序列消耗源石结晶时，返还50点技力。 | AB3: =VLOOKUP($A3&"_"&$C3, DataSource!$A:$AT, 29, FALSE) -> 【权能映射】天赋本质瓦解效果加强：自身获得攻击力提升时，其他友方干员获得一半的攻击力提升效果。 | AC3: =VLOOKUP($A3&"_"&$C3, DataSource!$A:$AT, 30, FALSE) -> 【？？？】？？？ | AD3: =VLOOKUP($A3&"_"&$C3, DataSource!$A:$AT, 31, FALSE) -> 【？？？】？？？ | AE3: =VLOOKUP($A3&"_"&$C3, DataSource!$A:$AT, 32, FALSE) -> 【？？？】？？？ | AF3: =VLOOKUP($A3&"_"&$C3, DataSource!$A:$AT, 33, FALSE) -> 【游刃】干员敏捷能力值提升10。 | AG3: =VLOOKUP($A3&"_"&$C3, DataSource!$A:$AT, 34, FALSE) -> 【游刃】干员敏捷能力值提升15。 | AH3: =VLOOKUP($A3&"_"&$C3, DataSource!$A:$AT, 35, FALSE) -> 【游刃】干员敏捷能力值提升15。 | AI3: =VLOOKUP($A3&"_"&$C3, DataSource!$A:$AT, 36, FALSE) -> 【游刃】干员敏捷能力值提升20。 | AJ3: 1 | AK3: =VLOOKUP($A3&"_"&$C3, DataSource!$A:$AT, 39 + AJ3 - 1, FALSE) -> 【本质瓦解 Lv.1】当敌人附着的源石结晶被消耗后，自身攻击力+15%，持续15秒，该效果无法叠加。 | AL3: 1 | AM3: =VLOOKUP($A3&"_"&$C3, DataSource!$A:$AT, 44 + AL3 - 1, FALSE) -> 【现实静滞 Lv.1】附着源石结晶的敌人受到的物理伤害+10%。
A4: chr_0003_endminf | B4: =VLOOKUP("chr_0003_endminf_90", DataSource!$A:$P, 3, FALSE) -> 管理员(女) | C4: 90 | D4: =VLOOKUP($A4&"_"&$C4, DataSource!$A:$AT, 5, FALSE) -> Endministrator | E4: =VLOOKUP($A4&"_"&$C4, DataSource!$A:$AT, 6, FALSE) -> 近卫 | F4: =VLOOKUP($A4&"_"&$C4, DataSource!$A:$AT, 7, FALSE) -> ENDFIELD INDUSTRIES | G4: =VLOOKUP($A4&"_"&$C4, DataSource!$A:$AT, 8, FALSE) -> 猛击, 控制 | H4: =VLOOKUP($A4&"_"&$C4, DataSource!$A:$AT, 9, FALSE) -> 6★ | I4: =VLOOKUP($A4&"_"&$C4, DataSource!$A:$AT, 10, FALSE) -> 单手剑 | J4: =VLOOKUP($A4&"_"&$C4, DataSource!$A:$AT, 11, FALSE) -> 物理 | K4: =VLOOKUP($A4&"_"&$C4, DataSource!$A:$AT, 12, FALSE) -> 敏捷 | L4: =VLOOKUP($A4&"_"&$C4, DataSource!$A:$AT, 13, FALSE) -> 力量 | M4: =VLOOKUP($A4&"_"&$C4, DataSource!$A:$AT, 14, FALSE) -> 5495 | N4: =VLOOKUP($A4&"_"&$C4, DataSource!$A:$AT, 15, FALSE) -> 319 | O4: =VLOOKUP($A4&"_"&$C4, DataSource!$A:$AT, 16, FALSE) -> 0 | P4: =VLOOKUP($A4&"_"&$C4, DataSource!$A:$AT, 17, FALSE) -> 123.70313486219221 | Q4: =VLOOKUP($A4&"_"&$C4, DataSource!$A:$AT, 18, FALSE) -> 140.84536082474185 | R4: =VLOOKUP($A4&"_"&$C4, DataSource!$A:$AT, 19, FALSE) -> 96.95876288659824 | S4: =VLOOKUP($A4&"_"&$C4, DataSource!$A:$AT, 20, FALSE) -> 107.16494845360792 | T4: =VLOOKUP($A4&"_"&$C4, DataSource!$A:$AT, 21, FALSE) -> 5.0% | U4: =VLOOKUP($A4&"_"&$C4, DataSource!$A:$AT, 22, FALSE) -> 50.0% | V4: =VLOOKUP($A4&"_"&$C4, DataSource!$A:$AT, 23, FALSE) -> 3 | W4: =VLOOKUP($A4&"_"&$C4, DataSource!$A:$AT, 24, FALSE) -> 0.14 | X4: =VLOOKUP($A4&"_"&$C4, DataSource!$A:$AT, 25, FALSE) -> 1.22704081632653 | Y4: =VLOOKUP($A4&"_"&$C4, DataSource!$A:$AT, 26, FALSE) -> 1.45408163265306 | Z4: =VLOOKUP($A4&"_"&$C4, DataSource!$A:$AT, 27, FALSE) -> 4 | AA4: =VLOOKUP($A4&"_"&$C4, DataSource!$A:$AT, 28, FALSE) -> 【最后的苏醒】战技构成序列消耗源石结晶时，返还50点技力。 | AB4: =VLOOKUP($A4&"_"&$C4, DataSource!$A:$AT, 29, FALSE) -> 【权能映射】天赋本质瓦解效果加强：自身获得攻击力提升时，其他友方干员获得一半的攻击力提升效果。 | AC4: =VLOOKUP($A4&"_"&$C4, DataSource!$A:$AT, 30, FALSE) -> 【？？？】？？？ | AD4: =VLOOKUP($A4&"_"&$C4, DataSource!$A:$AT, 31, FALSE) -> 【？？？】？？？ | AE4: =VLOOKUP($A4&"_"&$C4, DataSource!$A:$AT, 32, FALSE) -> 【？？？】？？？ | AF4: =VLOOKUP($A4&"_"&$C4, DataSource!$A:$AT, 33, FALSE) -> 【游刃】干员敏捷能力值提升10。 | AG4: =VLOOKUP($A4&"_"&$C4, DataSource!$A:$AT, 34, FALSE) -> 【游刃】干员敏捷能力值提升15。 | AH4: =VLOOKUP($A4&"_"&$C4, DataSource!$A:$AT, 35, FALSE) -> 【游刃】干员敏捷能力值提升15。 | AI4: =VLOOKUP($A4&"_"&$C4, DataSource!$A:$AT, 36, FALSE) -> 【游刃】干员敏捷能力值提升20。 | AJ4: 1 | AK4: =VLOOKUP($A4&"_"&$C4, DataSource!$A:$AT, 39 + AJ4 - 1, FALSE) -> 【本质瓦解 Lv.1】当敌人附着的源石结晶被消耗后，自身攻击力+15%，持续15秒，该效果无法叠加。 | AL4: 1 | AM4: =VLOOKUP($A4&"_"&$C4, DataSource!$A:$AT, 44 + AL4 - 1, FALSE) -> 【现实静滞 Lv.1】附着源石结晶的敌人受到的物理伤害+10%。
A5: chr_0004_pelica | B5: =VLOOKUP("chr_0004_pelica_90", DataSource!$A:$P, 3, FALSE) -> 佩丽卡 | C5: 90 | D5: =VLOOKUP($A5&"_"&$C5, DataSource!$A:$AT, 5, FALSE) -> Perlica | E5: =VLOOKUP($A5&"_"&$C5, DataSource!$A:$AT, 6, FALSE) -> 术师 | F5: =VLOOKUP($A5&"_"&$C5, DataSource!$A:$AT, 7, FALSE) -> ENDFIELD INDUSTRIES | G5: =VLOOKUP($A5&"_"&$C5, DataSource!$A:$AT, 8, FALSE) -> 电磁附着, 导电 | H5: =VLOOKUP($A5&"_"&$C5, DataSource!$A:$AT, 9, FALSE) -> 5★ | I5: =VLOOKUP($A5&"_"&$C5, DataSource!$A:$AT, 10, FALSE) -> 施术单元 | J5: =VLOOKUP($A5&"_"&$C5, DataSource!$A:$AT, 11, FALSE) -> 电磁 | K5: =VLOOKUP($A5&"_"&$C5, DataSource!$A:$AT, 12, FALSE) -> 智识 | L5: =VLOOKUP($A5&"_"&$C5, DataSource!$A:$AT, 13, FALSE) -> 意志 | M5: =VLOOKUP($A5&"_"&$C5, DataSource!$A:$AT, 14, FALSE) -> 5495 | N5: =VLOOKUP($A5&"_"&$C5, DataSource!$A:$AT, 15, FALSE) -> 303 | O5: =VLOOKUP($A5&"_"&$C5, DataSource!$A:$AT, 16, FALSE) -> 0 | P5: =VLOOKUP($A5&"_"&$C5, DataSource!$A:$AT, 17, FALSE) -> 91.8556701030925 | Q5: =VLOOKUP($A5&"_"&$C5, DataSource!$A:$AT, 18, FALSE) -> 93.89690721649515 | R5: =VLOOKUP($A5&"_"&$C5, DataSource!$A:$AT, 19, FALSE) -> 161.6994950557542 | S5: =VLOOKUP($A5&"_"&$C5, DataSource!$A:$AT, 20, FALSE) -> 113.58859667578378 | T5: =VLOOKUP($A5&"_"&$C5, DataSource!$A:$AT, 21, FALSE) -> 5.0% | U5: =VLOOKUP($A5&"_"&$C5, DataSource!$A:$AT, 22, FALSE) -> 50.0% | V5: =VLOOKUP($A5&"_"&$C5, DataSource!$A:$AT, 23, FALSE) -> 10 | W5: =VLOOKUP($A5&"_"&$C5, DataSource!$A:$AT, 24, FALSE) -> 0.13125 | X5: =VLOOKUP($A5&"_"&$C5, DataSource!$A:$AT, 25, FALSE) -> 1.22704081632653 | Y5: =VLOOKUP($A5&"_"&$C5, DataSource!$A:$AT, 26, FALSE) -> 1.45408163265306 | Z5: =VLOOKUP($A5&"_"&$C5, DataSource!$A:$AT, 27, FALSE) -> 4 | AA5: =VLOOKUP($A5&"_"&$C5, DataSource!$A:$AT, 28, FALSE) -> 【危机处理】连携技即时协议·闪链施加的导电持续时间+75%。 | AB5: =VLOOKUP($A5&"_"&$C5, DataSource!$A:$AT, 29, FALSE) -> 【谈判策略】终结技协议ε·70.41κ所需的终结技能量-15%。 | AC5: =VLOOKUP($A5&"_"&$C5, DataSource!$A:$AT, 30, FALSE) -> 【监督重任】当佩丽卡对敌人施加导电后，在5秒内攻击力+20%，该效果最多叠加2层。 | AD5: =VLOOKUP($A5&"_"&$C5, DataSource!$A:$AT, 31, FALSE) -> 【长效导流】连携技即时协议·闪链施加的导电使敌人受到法术伤害提高的效果提升至原本的1.33倍。 | AE5: =VLOOKUP($A5&"_"&$C5, DataSource!$A:$AT, 32, FALSE) -> 【再入控制】终结技协议ε·70.41κ的暴击率+30%。 | AF5: =VLOOKUP($A5&"_"&$C5, DataSource!$A:$AT, 33, FALSE) -> 【明晰】干员智识能力值提升15。 | AG5: =VLOOKUP($A5&"_"&$C5, DataSource!$A:$AT, 34, FALSE) -> 【明晰】干员智识能力值提升20。 | AH5: =VLOOKUP($A5&"_"&$C5, DataSource!$A:$AT, 35, FALSE) -> 【明晰】干员智识能力值提升10。 | AI5: =VLOOKUP($A5&"_"&$C5, DataSource!$A:$AT, 36, FALSE) -> 【明晰】干员智识能力值提升15。 | AJ5: 1 | AK5: =VLOOKUP($A5&"_"&$C5, DataSource!$A:$AT, 39 + AJ5 - 1, FALSE) -> 【循环协议 Lv.1】连携技即时协议·闪链命中处于破防状态的敌人时，还会弹射1次。 | AL5: 1 | AM5: =VLOOKUP($A5&"_"&$C5, DataSource!$A:$AT, 44 + AL5 - 1, FALSE) -> 【歼灭协议 Lv.1】对失衡的敌人造成的伤害+20%。
A6: chr_0005_chen | B6: =VLOOKUP("chr_0005_chen_90", DataSource!$A:$P, 3, FALSE) -> 陈千语 | C6: 90 | D6: =VLOOKUP($A6&"_"&$C6, DataSource!$A:$AT, 5, FALSE) -> Chen Qianyu | E6: =VLOOKUP($A6&"_"&$C6, DataSource!$A:$AT, 6, FALSE) -> 近卫 | F6: =VLOOKUP($A6&"_"&$C6, DataSource!$A:$AT, 7, FALSE) -> ENDFIELD INDUSTRIES | G6: =VLOOKUP($A6&"_"&$C6, DataSource!$A:$AT, 8, FALSE) -> 击飞, 失衡 | H6: =VLOOKUP($A6&"_"&$C6, DataSource!$A:$AT, 9, FALSE) -> 5★ | I6: =VLOOKUP($A6&"_"&$C6, DataSource!$A:$AT, 10, FALSE) -> 单手剑 | J6: =VLOOKUP($A6&"_"&$C6, DataSource!$A:$AT, 11, FALSE) -> 物理 | K6: =VLOOKUP($A6&"_"&$C6, DataSource!$A:$AT, 12, FALSE) -> 敏捷 | L6: =VLOOKUP($A6&"_"&$C6, DataSource!$A:$AT, 13, FALSE) -> 力量 | M6: =VLOOKUP($A6&"_"&$C6, DataSource!$A:$AT, 14, FALSE) -> 5495 | N6: =VLOOKUP($A6&"_"&$C6, DataSource!$A:$AT, 15, FALSE) -> 297 | O6: =VLOOKUP($A6&"_"&$C6, DataSource!$A:$AT, 16, FALSE) -> 0 | P6: =VLOOKUP($A6&"_"&$C6, DataSource!$A:$AT, 17, FALSE) -> 106.65463917525815 | Q6: =VLOOKUP($A6&"_"&$C6, DataSource!$A:$AT, 18, FALSE) -> 171.7621502209135 | R6: =VLOOKUP($A6&"_"&$C6, DataSource!$A:$AT, 19, FALSE) -> 85.75089417210184 | S6: =VLOOKUP($A6&"_"&$C6, DataSource!$A:$AT, 20, FALSE) -> 93.9158426257104 | T6: =VLOOKUP($A6&"_"&$C6, DataSource!$A:$AT, 21, FALSE) -> 5.0% | U6: =VLOOKUP($A6&"_"&$C6, DataSource!$A:$AT, 22, FALSE) -> 50.0% | V6: =VLOOKUP($A6&"_"&$C6, DataSource!$A:$AT, 23, FALSE) -> 3 | W6: =VLOOKUP($A6&"_"&$C6, DataSource!$A:$AT, 24, FALSE) -> 0.14 | X6: =VLOOKUP($A6&"_"&$C6, DataSource!$A:$AT, 25, FALSE) -> 1.22704081632653 | Y6: =VLOOKUP($A6&"_"&$C6, DataSource!$A:$AT, 26, FALSE) -> 1.45408163265306 | Z6: =VLOOKUP($A6&"_"&$C6, DataSource!$A:$AT, 27, FALSE) -> 4 | AA6: =VLOOKUP($A6&"_"&$C6, DataSource!$A:$AT, 28, FALSE) -> 【“绝影”】对生命值少于50%的敌人造成的伤害+20%。 | AB6: =VLOOKUP($A6&"_"&$C6, DataSource!$A:$AT, 29, FALSE) -> 【家传武学】敏捷+15，造成的物理伤害+8%。 | AC6: =VLOOKUP($A6&"_"&$C6, DataSource!$A:$AT, 30, FALSE) -> 【双剑奇侠】战技归穹宇、连携技见天河和终结技冽风霜的伤害倍率提升至原本的1.1倍。 | AD6: =VLOOKUP($A6&"_"&$C6, DataSource!$A:$AT, 31, FALSE) -> 【自研赤霄剑】终结技冽风霜所需的终结技能量-15%。 | AE6: =VLOOKUP($A6&"_"&$C6, DataSource!$A:$AT, 32, FALSE) -> 【心兼人间】连携技见天河的冷却时间-3秒。 | AF6: =VLOOKUP($A6&"_"&$C6, DataSource!$A:$AT, 33, FALSE) -> 【游刃】干员敏捷能力值提升15。 | AG6: =VLOOKUP($A6&"_"&$C6, DataSource!$A:$AT, 34, FALSE) -> 【游刃】干员敏捷能力值提升10。 | AH6: =VLOOKUP($A6&"_"&$C6, DataSource!$A:$AT, 35, FALSE) -> 【游刃】干员敏捷能力值提升15。 | AI6: =VLOOKUP($A6&"_"&$C6, DataSource!$A:$AT, 36, FALSE) -> 【游刃】干员敏捷能力值提升20。 | AJ6: 1 | AK6: =VLOOKUP($A6&"_"&$C6, DataSource!$A:$AT, 39 + AJ6 - 1, FALSE) -> 【斩锋 Lv.1】技能每次命中敌人后，攻击力+4%，持续10秒，该效果最多叠加5层。 | AL6: 1 | AM6: =VLOOKUP($A6&"_"&$C6, DataSource!$A:$AT, 44 + AL6 - 1, FALSE) -> 【破势 Lv.1】技能打断敌人蓄力时，额外对其造成5点失衡。
A7: chr_0006_wolfgd | B7: =VLOOKUP("chr_0006_wolfgd_90", DataSource!$A:$P, 3, FALSE) -> 狼卫 | C7: 90 | D7: =VLOOKUP($A7&"_"&$C7, DataSource!$A:$AT, 5, FALSE) -> Wulfgard | E7: =VLOOKUP($A7&"_"&$C7, DataSource!$A:$AT, 6, FALSE) -> 术师 | F7: =VLOOKUP($A7&"_"&$C7, DataSource!$A:$AT, 7, FALSE) -> ENDFIELD INDUSTRIES | G7: =VLOOKUP($A7&"_"&$C7, DataSource!$A:$AT, 8, FALSE) -> 灼热附着, 燃烧 | H7: =VLOOKUP($A7&"_"&$C7, DataSource!$A:$AT, 9, FALSE) -> 5★ | I7: =VLOOKUP($A7&"_"&$C7, DataSource!$A:$AT, 10, FALSE) -> 手铳 | J7: =VLOOKUP($A7&"_"&$C7, DataSource!$A:$AT, 11, FALSE) -> 灼热 | K7: =VLOOKUP($A7&"_"&$C7, DataSource!$A:$AT, 12, FALSE) -> 力量 | L7: =VLOOKUP($A7&"_"&$C7, DataSource!$A:$AT, 13, FALSE) -> 敏捷 | M7: =VLOOKUP($A7&"_"&$C7, DataSource!$A:$AT, 14, FALSE) -> 5495 | N7: =VLOOKUP($A7&"_"&$C7, DataSource!$A:$AT, 15, FALSE) -> 294 | O7: =VLOOKUP($A7&"_"&$C7, DataSource!$A:$AT, 16, FALSE) -> 0 | P7: =VLOOKUP($A7&"_"&$C7, DataSource!$A:$AT, 17, FALSE) -> 161.71880917315397 | Q7: =VLOOKUP($A7&"_"&$C7, DataSource!$A:$AT, 18, FALSE) -> 95.42783505154625 | R7: =VLOOKUP($A7&"_"&$C7, DataSource!$A:$AT, 19, FALSE) -> 92.87628865979384 | S7: =VLOOKUP($A7&"_"&$C7, DataSource!$A:$AT, 20, FALSE) -> 111.48411529560273 | T7: =VLOOKUP($A7&"_"&$C7, DataSource!$A:$AT, 21, FALSE) -> 5.0% | U7: =VLOOKUP($A7&"_"&$C7, DataSource!$A:$AT, 22, FALSE) -> 50.0% | V7: =VLOOKUP($A7&"_"&$C7, DataSource!$A:$AT, 23, FALSE) -> 10 | W7: =VLOOKUP($A7&"_"&$C7, DataSource!$A:$AT, 24, FALSE) -> 0.105 | X7: =VLOOKUP($A7&"_"&$C7, DataSource!$A:$AT, 25, FALSE) -> 1.22704081632653 | Y7: =VLOOKUP($A7&"_"&$C7, DataSource!$A:$AT, 26, FALSE) -> 1.45408163265306 | Z7: =VLOOKUP($A7&"_"&$C7, DataSource!$A:$AT, 27, FALSE) -> 4 | AA7: =VLOOKUP($A7&"_"&$C7, DataSource!$A:$AT, 28, FALSE) -> 【独狼】力量+15，敏捷+15。 | AB7: =VLOOKUP($A7&"_"&$C7, DataSource!$A:$AT, 29, FALSE) -> 【铳械改造】天赋节制准则效果加强：额外返还10点技力。 | AC7: =VLOOKUP($A7&"_"&$C7, DataSource!$A:$AT, 30, FALSE) -> 【狩猎时刻】灼热獠牙状态下，施放战技触发额外效果时，立即刷新自身灼热獠牙状态的持续时间，同时使小队内其他干员获得灼热獠牙，效果为基础的50%。 | AD7: =VLOOKUP($A7&"_"&$C7, DataSource!$A:$AT, 31, FALSE) -> 【狼群意志】终结技狼之怒所需的终结技能量-15%。 | AE7: =VLOOKUP($A7&"_"&$C7, DataSource!$A:$AT, 32, FALSE) -> 【天生掠食者】施放终结技狼之怒后立即刷新连携技爆裂手雷·β型冷却时间。 | AF7: =VLOOKUP($A7&"_"&$C7, DataSource!$A:$AT, 33, FALSE) -> 【锤炼】干员力量能力值提升10。 | AG7: =VLOOKUP($A7&"_"&$C7, DataSource!$A:$AT, 34, FALSE) -> 【锤炼】干员力量能力值提升15。 | AH7: =VLOOKUP($A7&"_"&$C7, DataSource!$A:$AT, 35, FALSE) -> 【锤炼】干员力量能力值提升15。 | AI7: =VLOOKUP($A7&"_"&$C7, DataSource!$A:$AT, 36, FALSE) -> 【锤炼】干员力量能力值提升20。 | AJ7: 1 | AK7: =VLOOKUP($A7&"_"&$C7, DataSource!$A:$AT, 39 + AJ7 - 1, FALSE) -> 【灼热獠牙 Lv.1】每次施加燃烧后，获得灼热獠牙状态，持续10秒，该状态无法叠加。状态持续期间，自身造成的灼热伤害+20%。 | AL7: 1 | AM7: =VLOOKUP($A7&"_"&$C7, DataSource!$A:$AT, 44 + AL7 - 1, FALSE) -> 【节制准则 Lv.1】战技灼热弹痕成功消耗法术异常时，返还5点技力。
A8: chr_0007_ikut | B8: =VLOOKUP("chr_0007_ikut_90", DataSource!$A:$P, 3, FALSE) -> 弧光 | C8: 90 | D8: =VLOOKUP($A8&"_"&$C8, DataSource!$A:$AT, 5, FALSE) -> Arclight | E8: =VLOOKUP($A8&"_"&$C8, DataSource!$A:$AT, 6, FALSE) -> 先锋 | F8: =VLOOKUP($A8&"_"&$C8, DataSource!$A:$AT, 7, FALSE) -> ENDFIELD INDUSTRIES | G8: =VLOOKUP($A8&"_"&$C8, DataSource!$A:$AT, 8, FALSE) -> 技力恢复, 电磁附着 | H8: =VLOOKUP($A8&"_"&$C8, DataSource!$A:$AT, 9, FALSE) -> 5★ | I8: =VLOOKUP($A8&"_"&$C8, DataSource!$A:$AT, 10, FALSE) -> 单手剑 | J8: =VLOOKUP($A8&"_"&$C8, DataSource!$A:$AT, 11, FALSE) -> 电磁 | K8: =VLOOKUP($A8&"_"&$C8, DataSource!$A:$AT, 12, FALSE) -> 敏捷 | L8: =VLOOKUP($A8&"_"&$C8, DataSource!$A:$AT, 13, FALSE) -> 智识 | M8: =VLOOKUP($A8&"_"&$C8, DataSource!$A:$AT, 14, FALSE) -> 5495 | N8: =VLOOKUP($A8&"_"&$C8, DataSource!$A:$AT, 15, FALSE) -> 306 | O8: =VLOOKUP($A8&"_"&$C8, DataSource!$A:$AT, 16, FALSE) -> 0 | P8: =VLOOKUP($A8&"_"&$C8, DataSource!$A:$AT, 17, FALSE) -> 107.45844729644404 | Q8: =VLOOKUP($A8&"_"&$C8, DataSource!$A:$AT, 18, FALSE) -> 145.43814432989691 | R8: =VLOOKUP($A8&"_"&$C8, DataSource!$A:$AT, 19, FALSE) -> 123.49484536082466 | S8: =VLOOKUP($A8&"_"&$C8, DataSource!$A:$AT, 20, FALSE) -> 100.02061855670134 | T8: =VLOOKUP($A8&"_"&$C8, DataSource!$A:$AT, 21, FALSE) -> 5.0% | U8: =VLOOKUP($A8&"_"&$C8, DataSource!$A:$AT, 22, FALSE) -> 50.0% | V8: =VLOOKUP($A8&"_"&$C8, DataSource!$A:$AT, 23, FALSE) -> 5 | W8: =VLOOKUP($A8&"_"&$C8, DataSource!$A:$AT, 24, FALSE) -> 0.14875 | X8: =VLOOKUP($A8&"_"&$C8, DataSource!$A:$AT, 25, FALSE) -> 1.22704081632653 | Y8: =VLOOKUP($A8&"_"&$C8, DataSource!$A:$AT, 26, FALSE) -> 1.45408163265306 | Z8: =VLOOKUP($A8&"_"&$C8, DataSource!$A:$AT, 27, FALSE) -> 4 | AA8: =VLOOKUP($A8&"_"&$C8, DataSource!$A:$AT, 28, FALSE) -> 【风暴中的孩子】使用战技疾风迅雷成功触发额外效果后，额外恢复10点技力。 | AB8: =VLOOKUP($A8&"_"&$C8, DataSource!$A:$AT, 29, FALSE) -> 【速战速决】敏捷+15，智识+15。 | AC8: =VLOOKUP($A8&"_"&$C8, DataSource!$A:$AT, 30, FALSE) -> 【“歌谣”】天赋荒野游人效果加强：伤害提升效果提升至原本的1.3倍。 | AD8: =VLOOKUP($A8&"_"&$C8, DataSource!$A:$AT, 31, FALSE) -> 【师者教诲】终结技轰雷掣电所需的终结技能量-15%。 | AE8: =VLOOKUP($A8&"_"&$C8, DataSource!$A:$AT, 32, FALSE) -> 【荒野的徒从】天赋荒野游人效果加强：触发所需次数降低至2次。 | AF8: =VLOOKUP($A8&"_"&$C8, DataSource!$A:$AT, 33, FALSE) -> 【游刃】干员敏捷能力值提升15。 | AG8: =VLOOKUP($A8&"_"&$C8, DataSource!$A:$AT, 34, FALSE) -> 【游刃】干员敏捷能力值提升10。 | AH8: =VLOOKUP($A8&"_"&$C8, DataSource!$A:$AT, 35, FALSE) -> 【游刃】干员敏捷能力值提升15。 | AI8: =VLOOKUP($A8&"_"&$C8, DataSource!$A:$AT, 36, FALSE) -> 【游刃】干员敏捷能力值提升20。 | AJ8: 1 | AK8: =VLOOKUP($A8&"_"&$C8, DataSource!$A:$AT, 39 + AJ8 - 1, FALSE) -> 【众生智慧 Lv.1】被施加法术附着时，有30%的概率忽略该效果。 | AL8: 1 | AM8: =VLOOKUP($A8&"_"&$C8, DataSource!$A:$AT, 44 + AL8 - 1, FALSE) -> 【荒野游人 Lv.1】使用战技疾风迅雷成功触发3次额外效果后，根据自身的智识，提升全队造成的电磁伤害，每点智识+0.05%，持续15秒，该效果无法叠加。
A9: chr_0009_azrila | B9: =VLOOKUP("chr_0009_azrila_90", DataSource!$A:$P, 3, FALSE) -> 余烬 | C9: 90 | D9: =VLOOKUP($A9&"_"&$C9, DataSource!$A:$AT, 5, FALSE) -> Ember | E9: =VLOOKUP($A9&"_"&$C9, DataSource!$A:$AT, 6, FALSE) -> 重装 | F9: =VLOOKUP($A9&"_"&$C9, DataSource!$A:$AT, 7, FALSE) -> ENDFIELD INDUSTRIES | G9: =VLOOKUP($A9&"_"&$C9, DataSource!$A:$AT, 8, FALSE) -> 倒地, 治疗, 护盾 | H9: =VLOOKUP($A9&"_"&$C9, DataSource!$A:$AT, 9, FALSE) -> 6★ | I9: =VLOOKUP($A9&"_"&$C9, DataSource!$A:$AT, 10, FALSE) -> 双手剑 | J9: =VLOOKUP($A9&"_"&$C9, DataSource!$A:$AT, 11, FALSE) -> 灼热 | K9: =VLOOKUP($A9&"_"&$C9, DataSource!$A:$AT, 12, FALSE) -> 力量 | L9: =VLOOKUP($A9&"_"&$C9, DataSource!$A:$AT, 13, FALSE) -> 意志 | M9: =VLOOKUP($A9&"_"&$C9, DataSource!$A:$AT, 14, FALSE) -> 5495 | N9: =VLOOKUP($A9&"_"&$C9, DataSource!$A:$AT, 15, FALSE) -> 323 | O9: =VLOOKUP($A9&"_"&$C9, DataSource!$A:$AT, 16, FALSE) -> 0 | P9: =VLOOKUP($A9&"_"&$C9, DataSource!$A:$AT, 17, FALSE) -> 176.41173995371338 | Q9: =VLOOKUP($A9&"_"&$C9, DataSource!$A:$AT, 18, FALSE) -> 96.95876288659824 | R9: =VLOOKUP($A9&"_"&$C9, DataSource!$A:$AT, 19, FALSE) -> 86.75257731958767 | S9: =VLOOKUP($A9&"_"&$C9, DataSource!$A:$AT, 20, FALSE) -> 120.26219229959992 | T9: =VLOOKUP($A9&"_"&$C9, DataSource!$A:$AT, 21, FALSE) -> 5.0% | U9: =VLOOKUP($A9&"_"&$C9, DataSource!$A:$AT, 22, FALSE) -> 50.0% | V9: =VLOOKUP($A9&"_"&$C9, DataSource!$A:$AT, 23, FALSE) -> 3 | W9: =VLOOKUP($A9&"_"&$C9, DataSource!$A:$AT, 24, FALSE) -> 0.0958125 | X9: =VLOOKUP($A9&"_"&$C9, DataSource!$A:$AT, 25, FALSE) -> 1.22704081632653 | Y9: =VLOOKUP($A9&"_"&$C9, DataSource!$A:$AT, 26, FALSE) -> 1.45408163265306 | Z9: =VLOOKUP($A9&"_"&$C9, DataSource!$A:$AT, 27, FALSE) -> 4 | AA9: =VLOOKUP($A9&"_"&$C9, DataSource!$A:$AT, 28, FALSE) -> 【移动要塞】天赋陷阵之志效果加强：庇护效果额外+20%，且在命中敌人后额外持续1.5秒。 | AB9: =VLOOKUP($A9&"_"&$C9, DataSource!$A:$AT, 29, FALSE) -> 【百战成钢】力量+20，意志+20。 | AC9: =VLOOKUP($A9&"_"&$C9, DataSource!$A:$AT, 30, FALSE) -> 【不屈阵线】连携技前线援护会额外治疗小队内另一个生命值百分比最低的干员，效果为基础的50%。 | AD9: =VLOOKUP($A9&"_"&$C9, DataSource!$A:$AT, 31, FALSE) -> 【薪火不息】终结技重燃誓约所需的终结技能量-15%。 | AE9: =VLOOKUP($A9&"_"&$C9, DataSource!$A:$AT, 32, FALSE) -> 【铁誓】终结技重燃誓约提供的护盾效果变为1.2倍，且该护盾存在期间持有者攻击力+10%。 | AF9: =VLOOKUP($A9&"_"&$C9, DataSource!$A:$AT, 33, FALSE) -> 【锤炼】干员力量能力值提升15。 | AG9: =VLOOKUP($A9&"_"&$C9, DataSource!$A:$AT, 34, FALSE) -> 【锤炼】干员力量能力值提升10。 | AH9: =VLOOKUP($A9&"_"&$C9, DataSource!$A:$AT, 35, FALSE) -> 【锤炼】干员力量能力值提升15。 | AI9: =VLOOKUP($A9&"_"&$C9, DataSource!$A:$AT, 36, FALSE) -> 【锤炼】干员力量能力值提升20。 | AJ9: 1 | AK9: =VLOOKUP($A9&"_"&$C9, DataSource!$A:$AT, 39 + AJ9 - 1, FALSE) -> 【陷阵之志 Lv.1】战技进军和连携技前线援护的施放过程中获得30%庇护，且更不容易被打断。 | AL9: 1 | AM9: =VLOOKUP($A9&"_"&$C9, DataSource!$A:$AT, 44 + AL9 - 1, FALSE) -> 【以铁还铁 Lv.1】受到来自敌人的伤害后，攻击力+6%，持续7秒，该效果最多叠加3层。
A10: chr_0011_seraph | B10: =VLOOKUP("chr_0011_seraph_90", DataSource!$A:$P, 3, FALSE) -> 赛希 | C10: 90 | D10: =VLOOKUP($A10&"_"&$C10, DataSource!$A:$AT, 5, FALSE) -> Xaihi | E10: =VLOOKUP($A10&"_"&$C10, DataSource!$A:$AT, 6, FALSE) -> 辅助 | F10: =VLOOKUP($A10&"_"&$C10, DataSource!$A:$AT, 7, FALSE) -> ENDFIELD INDUSTRIES | G10: =VLOOKUP($A10&"_"&$C10, DataSource!$A:$AT, 8, FALSE) -> 治疗, 寒冷附着, 增幅 | H10: =VLOOKUP($A10&"_"&$C10, DataSource!$A:$AT, 9, FALSE) -> 5★ | I10: =VLOOKUP($A10&"_"&$C10, DataSource!$A:$AT, 10, FALSE) -> 施术单元 | J10: =VLOOKUP($A10&"_"&$C10, DataSource!$A:$AT, 11, FALSE) -> 寒冷 | K10: =VLOOKUP($A10&"_"&$C10, DataSource!$A:$AT, 12, FALSE) -> 意志 | L10: =VLOOKUP($A10&"_"&$C10, DataSource!$A:$AT, 13, FALSE) -> 智识 | M10: =VLOOKUP($A10&"_"&$C10, DataSource!$A:$AT, 14, FALSE) -> 5495 | N10: =VLOOKUP($A10&"_"&$C10, DataSource!$A:$AT, 15, FALSE) -> 291 | O10: =VLOOKUP($A10&"_"&$C10, DataSource!$A:$AT, 16, FALSE) -> 0 | P10: =VLOOKUP($A10&"_"&$C10, DataSource!$A:$AT, 17, FALSE) -> 89.83810225120979 | Q10: =VLOOKUP($A10&"_"&$C10, DataSource!$A:$AT, 18, FALSE) -> 91.86513780770011 | R10: =VLOOKUP($A10&"_"&$C10, DataSource!$A:$AT, 19, FALSE) -> 127.14407742478453 | S10: =VLOOKUP($A10&"_"&$C10, DataSource!$A:$AT, 20, FALSE) -> 150.03092783505198 | T10: =VLOOKUP($A10&"_"&$C10, DataSource!$A:$AT, 21, FALSE) -> 5.0% | U10: =VLOOKUP($A10&"_"&$C10, DataSource!$A:$AT, 22, FALSE) -> 50.0% | V10: =VLOOKUP($A10&"_"&$C10, DataSource!$A:$AT, 23, FALSE) -> 10 | W10: =VLOOKUP($A10&"_"&$C10, DataSource!$A:$AT, 24, FALSE) -> 0.13 | X10: =VLOOKUP($A10&"_"&$C10, DataSource!$A:$AT, 25, FALSE) -> 1.22704081632653 | Y10: =VLOOKUP($A10&"_"&$C10, DataSource!$A:$AT, 26, FALSE) -> 1.45408163265306 | Z10: =VLOOKUP($A10&"_"&$C10, DataSource!$A:$AT, 27, FALSE) -> 4 | AA10: =VLOOKUP($A10&"_"&$C10, DataSource!$A:$AT, 28, FALSE) -> 【敏捷实践】支援晶体提供的法术增幅额外提高5%。 | AB10: =VLOOKUP($A10&"_"&$C10, DataSource!$A:$AT, 29, FALSE) -> 【链路聚合】终结技栈溢出所需的终结技能量-10%。 | AC10: =VLOOKUP($A10&"_"&$C10, DataSource!$A:$AT, 30, FALSE) -> 【映射节点】连携技压力测试命中目标时，对周围1个其他目标弹射1次。 | AD10: =VLOOKUP($A10&"_"&$C10, DataSource!$A:$AT, 31, FALSE) -> 【灰度发布】智识+15，治疗效率+10%。 | AE10: =VLOOKUP($A10&"_"&$C10, DataSource!$A:$AT, 32, FALSE) -> 【可控递归】终结技栈溢出提供的增幅效果提高至原本的1.1倍。 | AF10: =VLOOKUP($A10&"_"&$C10, DataSource!$A:$AT, 33, FALSE) -> 【守誓】干员意志能力值提升15。 | AG10: =VLOOKUP($A10&"_"&$C10, DataSource!$A:$AT, 34, FALSE) -> 【守誓】干员意志能力值提升10。 | AH10: =VLOOKUP($A10&"_"&$C10, DataSource!$A:$AT, 35, FALSE) -> 【守誓】干员意志能力值提升15。 | AI10: =VLOOKUP($A10&"_"&$C10, DataSource!$A:$AT, 36, FALSE) -> 【守誓】干员意志能力值提升20。 | AJ10: 1 | AK10: =VLOOKUP($A10&"_"&$C10, DataSource!$A:$AT, 39 + AJ10 - 1, FALSE) -> 【启动进程 Lv.1】连携技压力测试命中敌人时，如果目标已经处于寒冷附着或冻结状态，还会使目标受到的寒冷伤害+7%，持续5秒，该效果无法叠加。 | AL10: 1 | AM10: =VLOOKUP($A10&"_"&$C10, DataSource!$A:$AT, 44 + AL10 - 1, FALSE) -> 【协议冻结 Lv.1】终结技栈溢出会额外净化全队的寒冷附着和冻结状态。
A11: chr_0012_avywen | B11: =VLOOKUP("chr_0012_avywen_90", DataSource!$A:$P, 3, FALSE) -> 艾维文娜 | C11: 90 | D11: =VLOOKUP($A11&"_"&$C11, DataSource!$A:$AT, 5, FALSE) -> Avywenna | E11: =VLOOKUP($A11&"_"&$C11, DataSource!$A:$AT, 6, FALSE) -> 突击 | F11: =VLOOKUP($A11&"_"&$C11, DataSource!$A:$AT, 7, FALSE) -> ENDFIELD INDUSTRIES | G11: =VLOOKUP($A11&"_"&$C11, DataSource!$A:$AT, 8, FALSE) -> 大量伤害, 法术脆弱 | H11: =VLOOKUP($A11&"_"&$C11, DataSource!$A:$AT, 9, FALSE) -> 5★ | I11: =VLOOKUP($A11&"_"&$C11, DataSource!$A:$AT, 10, FALSE) -> 长柄武器 | J11: =VLOOKUP($A11&"_"&$C11, DataSource!$A:$AT, 11, FALSE) -> 电磁 | K11: =VLOOKUP($A11&"_"&$C11, DataSource!$A:$AT, 12, FALSE) -> 意志 | L11: =VLOOKUP($A11&"_"&$C11, DataSource!$A:$AT, 13, FALSE) -> 敏捷 | M11: =VLOOKUP($A11&"_"&$C11, DataSource!$A:$AT, 14, FALSE) -> 5495 | N11: =VLOOKUP($A11&"_"&$C11, DataSource!$A:$AT, 15, FALSE) -> 312 | O11: =VLOOKUP($A11&"_"&$C11, DataSource!$A:$AT, 16, FALSE) -> 0 | P11: =VLOOKUP($A11&"_"&$C11, DataSource!$A:$AT, 17, FALSE) -> 107.35430254576025 | Q11: =VLOOKUP($A11&"_"&$C11, DataSource!$A:$AT, 18, FALSE) -> 106.65463917525815 | R11: =VLOOKUP($A11&"_"&$C11, DataSource!$A:$AT, 19, FALSE) -> 110.50136755733189 | S11: =VLOOKUP($A11&"_"&$C11, DataSource!$A:$AT, 20, FALSE) -> 148.5 | T11: =VLOOKUP($A11&"_"&$C11, DataSource!$A:$AT, 21, FALSE) -> 5.0% | U11: =VLOOKUP($A11&"_"&$C11, DataSource!$A:$AT, 22, FALSE) -> 50.0% | V11: =VLOOKUP($A11&"_"&$C11, DataSource!$A:$AT, 23, FALSE) -> 3 | W11: =VLOOKUP($A11&"_"&$C11, DataSource!$A:$AT, 24, FALSE) -> 0.133875 | X11: =VLOOKUP($A11&"_"&$C11, DataSource!$A:$AT, 25, FALSE) -> 1.22704081632653 | Y11: =VLOOKUP($A11&"_"&$C11, DataSource!$A:$AT, 26, FALSE) -> 1.45408163265306 | Z11: =VLOOKUP($A11&"_"&$C11, DataSource!$A:$AT, 27, FALSE) -> 4 | AA11: =VLOOKUP($A11&"_"&$C11, DataSource!$A:$AT, 28, FALSE) -> 【筹码加倍】天赋高效派送效果加强：获得的终结技能量+2点。 | AB11: =VLOOKUP($A11&"_"&$C11, DataSource!$A:$AT, 29, FALSE) -> 【大棒悬头】雷枪、强雷枪的存在时间+20秒。 | AC11: =VLOOKUP($A11&"_"&$C11, DataSource!$A:$AT, 30, FALSE) -> 【绝不让步】意志+15，造成的电磁伤害+8%。 | AD11: =VLOOKUP($A11&"_"&$C11, DataSource!$A:$AT, 31, FALSE) -> 【经验老到】终结技雷枪·决颤所需的终结技能量-15%。 | AE11: =VLOOKUP($A11&"_"&$C11, DataSource!$A:$AT, 32, FALSE) -> 【恩威并施】召回的雷枪、强雷枪命中处于电磁脆弱状态的敌人时，伤害倍率提升至原本的1.15倍。 | AF11: =VLOOKUP($A11&"_"&$C11, DataSource!$A:$AT, 33, FALSE) -> 【守誓】干员意志能力值提升15。 | AG11: =VLOOKUP($A11&"_"&$C11, DataSource!$A:$AT, 34, FALSE) -> 【守誓】干员意志能力值提升10。 | AH11: =VLOOKUP($A11&"_"&$C11, DataSource!$A:$AT, 35, FALSE) -> 【守誓】干员意志能力值提升15。 | AI11: =VLOOKUP($A11&"_"&$C11, DataSource!$A:$AT, 36, FALSE) -> 【守誓】干员意志能力值提升20。 | AJ11: 1 | AK11: =VLOOKUP($A11&"_"&$C11, DataSource!$A:$AT, 39 + AJ11 - 1, FALSE) -> 【高效派送 Lv.1】掷出、召回雷枪、强雷枪命中敌人后，获得3点终结技能量。 | AL11: 1 | AM11: =VLOOKUP($A11&"_"&$C11, DataSource!$A:$AT, 44 + AL11 - 1, FALSE) -> 【委婉手段 Lv.1】终结技雷枪·决颤命中敌人时对其施加6%电磁脆弱，持续10秒。
A12: chr_0013_aglina | B12: =VLOOKUP("chr_0013_aglina_90", DataSource!$A:$P, 3, FALSE) -> 洁尔佩塔 | C12: 90 | D12: =VLOOKUP($A12&"_"&$C12, DataSource!$A:$AT, 5, FALSE) -> Gilberta | E12: =VLOOKUP($A12&"_"&$C12, DataSource!$A:$AT, 6, FALSE) -> 辅助 | F12: =VLOOKUP($A12&"_"&$C12, DataSource!$A:$AT, 7, FALSE) -> ENDFIELD INDUSTRIES | G12: =VLOOKUP($A12&"_"&$C12, DataSource!$A:$AT, 8, FALSE) -> 法术脆弱, 自然附着, 击飞 | H12: =VLOOKUP($A12&"_"&$C12, DataSource!$A:$AT, 9, FALSE) -> 6★ | I12: =VLOOKUP($A12&"_"&$C12, DataSource!$A:$AT, 10, FALSE) -> 施术单元 | J12: =VLOOKUP($A12&"_"&$C12, DataSource!$A:$AT, 11, FALSE) -> 自然 | K12: =VLOOKUP($A12&"_"&$C12, DataSource!$A:$AT, 12, FALSE) -> 意志 | L12: =VLOOKUP($A12&"_"&$C12, DataSource!$A:$AT, 13, FALSE) -> 智识 | M12: =VLOOKUP($A12&"_"&$C12, DataSource!$A:$AT, 14, FALSE) -> 5495 | N12: =VLOOKUP($A12&"_"&$C12, DataSource!$A:$AT, 15, FALSE) -> 329 | O12: =VLOOKUP($A12&"_"&$C12, DataSource!$A:$AT, 16, FALSE) -> 0 | P12: =VLOOKUP($A12&"_"&$C12, DataSource!$A:$AT, 17, FALSE) -> 89.81443298969076 | Q12: =VLOOKUP($A12&"_"&$C12, DataSource!$A:$AT, 18, FALSE) -> 92.87628865979384 | R12: =VLOOKUP($A12&"_"&$C12, DataSource!$A:$AT, 19, FALSE) -> 127.16490637492129 | S12: =VLOOKUP($A12&"_"&$C12, DataSource!$A:$AT, 20, FALSE) -> 171.74794866400205 | T12: =VLOOKUP($A12&"_"&$C12, DataSource!$A:$AT, 21, FALSE) -> 5.0% | U12: =VLOOKUP($A12&"_"&$C12, DataSource!$A:$AT, 22, FALSE) -> 50.0% | V12: =VLOOKUP($A12&"_"&$C12, DataSource!$A:$AT, 23, FALSE) -> 10 | W12: =VLOOKUP($A12&"_"&$C12, DataSource!$A:$AT, 24, FALSE) -> 0.1238125 | X12: =VLOOKUP($A12&"_"&$C12, DataSource!$A:$AT, 25, FALSE) -> 1.22704081632653 | Y12: =VLOOKUP($A12&"_"&$C12, DataSource!$A:$AT, 26, FALSE) -> 1.45408163265306 | Z12: =VLOOKUP($A12&"_"&$C12, DataSource!$A:$AT, 27, FALSE) -> 4 | AA12: =VLOOKUP($A12&"_"&$C12, DataSource!$A:$AT, 28, FALSE) -> 【云层之上】战技秘杖·引力模式的作用范围+20%。 | AB12: =VLOOKUP($A12&"_"&$C12, DataSource!$A:$AT, 29, FALSE) -> 【乘风而行】敌人受到终结技秘杖·重力场的重力紊乱区域影响时，每层破防状态对法术脆弱的提升效果加倍，且结算时视为目标额外拥有1层破防（不超过4层）。 | AC12: =VLOOKUP($A12&"_"&$C12, DataSource!$A:$AT, 30, FALSE) -> 【轻盈脚步】天赋信使的歌声效果加强：终结技充能效率额外+5%。 | AD12: =VLOOKUP($A12&"_"&$C12, DataSource!$A:$AT, 31, FALSE) -> 【云间舞踏】终结技秘杖·重力场所需的终结技能量-15%。 | AE12: =VLOOKUP($A12&"_"&$C12, DataSource!$A:$AT, 32, FALSE) -> 【特别信件】连携技秘杖·矩阵位移冷却时间-2秒，伤害倍率提升至原本的1.3倍。 | AF12: =VLOOKUP($A12&"_"&$C12, DataSource!$A:$AT, 33, FALSE) -> 【守誓】干员意志能力值提升20。 | AG12: =VLOOKUP($A12&"_"&$C12, DataSource!$A:$AT, 34, FALSE) -> 【守誓】干员意志能力值提升10。 | AH12: =VLOOKUP($A12&"_"&$C12, DataSource!$A:$AT, 35, FALSE) -> 【守誓】干员意志能力值提升15。 | AI12: =VLOOKUP($A12&"_"&$C12, DataSource!$A:$AT, 36, FALSE) -> 【守誓】干员意志能力值提升15。 | AJ12: 1 | AK12: =VLOOKUP($A12&"_"&$C12, DataSource!$A:$AT, 39 + AJ12 - 1, FALSE) -> 【信使的歌声 Lv.1】在场时，使小队内所有友方近卫、术师和辅助干员终结技充能效率+4%。 | AL12: 1 | AM12: =VLOOKUP($A12&"_"&$C12, DataSource!$A:$AT, 44 + AL12 - 1, FALSE) -> 【迟来的回信 Lv.1】战技秘杖·引力模式、连携技秘杖·矩阵位移效果加强：战技秘杖·引力模式最后一击或连携技秘杖·矩阵位移命中至少两个敌人后，回复主控干员[72+智识×0.6]生命值。主控干员生命值已满时，将转而治疗小队中生命值百分比最低的干员。
A13: chr_0014_aurora | B13: =VLOOKUP("chr_0014_aurora_90", DataSource!$A:$P, 3, FALSE) -> 昼雪 | C13: 90 | D13: =VLOOKUP($A13&"_"&$C13, DataSource!$A:$AT, 5, FALSE) -> Snowshine | E13: =VLOOKUP($A13&"_"&$C13, DataSource!$A:$AT, 6, FALSE) -> 重装 | F13: =VLOOKUP($A13&"_"&$C13, DataSource!$A:$AT, 7, FALSE) -> ENDFIELD INDUSTRIES | G13: =VLOOKUP($A13&"_"&$C13, DataSource!$A:$AT, 8, FALSE) -> 庇护, 治疗, 寒冷附着 | H13: =VLOOKUP($A13&"_"&$C13, DataSource!$A:$AT, 9, FALSE) -> 5★ | I13: =VLOOKUP($A13&"_"&$C13, DataSource!$A:$AT, 10, FALSE) -> 双手剑 | J13: =VLOOKUP($A13&"_"&$C13, DataSource!$A:$AT, 11, FALSE) -> 寒冷 | K13: =VLOOKUP($A13&"_"&$C13, DataSource!$A:$AT, 12, FALSE) -> 力量 | L13: =VLOOKUP($A13&"_"&$C13, DataSource!$A:$AT, 13, FALSE) -> 意志 | M13: =VLOOKUP($A13&"_"&$C13, DataSource!$A:$AT, 14, FALSE) -> 5495 | N13: =VLOOKUP($A13&"_"&$C13, DataSource!$A:$AT, 15, FALSE) -> 297 | O13: =VLOOKUP($A13&"_"&$C13, DataSource!$A:$AT, 16, FALSE) -> 0 | P13: =VLOOKUP($A13&"_"&$C13, DataSource!$A:$AT, 17, FALSE) -> 154.89354092152323 | Q13: =VLOOKUP($A13&"_"&$C13, DataSource!$A:$AT, 18, FALSE) -> 104.57685672207023 | R13: =VLOOKUP($A13&"_"&$C13, DataSource!$A:$AT, 19, FALSE) -> 93.89690721649515 | S13: =VLOOKUP($A13&"_"&$C13, DataSource!$A:$AT, 20, FALSE) -> 108.89999999999999 | T13: =VLOOKUP($A13&"_"&$C13, DataSource!$A:$AT, 21, FALSE) -> 5.0% | U13: =VLOOKUP($A13&"_"&$C13, DataSource!$A:$AT, 22, FALSE) -> 50.0% | V13: =VLOOKUP($A13&"_"&$C13, DataSource!$A:$AT, 23, FALSE) -> 3 | W13: =VLOOKUP($A13&"_"&$C13, DataSource!$A:$AT, 24, FALSE) -> 0.083125 | X13: =VLOOKUP($A13&"_"&$C13, DataSource!$A:$AT, 25, FALSE) -> 1.22704081632653 | Y13: =VLOOKUP($A13&"_"&$C13, DataSource!$A:$AT, 26, FALSE) -> 1.45408163265306 | Z13: =VLOOKUP($A13&"_"&$C13, DataSource!$A:$AT, 27, FALSE) -> 4 | AA13: =VLOOKUP($A13&"_"&$C13, DataSource!$A:$AT, 28, FALSE) -> 【失温庇护所】战技饱和性防御的格挡效果持续期间，处于庇护状态的友方干员无法被施加法术附着效果。 | AB13: =VLOOKUP($A13&"_"&$C13, DataSource!$A:$AT, 29, FALSE) -> 【暴风雪地带】终结技凛冽寒霜的影响范围+20%。 | AC13: =VLOOKUP($A13&"_"&$C13, DataSource!$A:$AT, 30, FALSE) -> 【极地生存指南】终结技凛冽寒霜施加的冻结的持续时间+2秒。 | AD13: =VLOOKUP($A13&"_"&$C13, DataSource!$A:$AT, 31, FALSE) -> 【冻土坚盾】防御力+20，意志+20。 | AE13: =VLOOKUP($A13&"_"&$C13, DataSource!$A:$AT, 32, FALSE) -> 【冰灾应对专家】战技饱和性防御成功反击敌人时，返还10点技力。 | AF13: =VLOOKUP($A13&"_"&$C13, DataSource!$A:$AT, 33, FALSE) -> 【锤炼】干员力量能力值提升10。 | AG13: =VLOOKUP($A13&"_"&$C13, DataSource!$A:$AT, 34, FALSE) -> 【锤炼】干员力量能力值提升15。 | AH13: =VLOOKUP($A13&"_"&$C13, DataSource!$A:$AT, 35, FALSE) -> 【锤炼】干员力量能力值提升15。 | AI13: =VLOOKUP($A13&"_"&$C13, DataSource!$A:$AT, 36, FALSE) -> 【锤炼】干员力量能力值提升20。 | AJ13: 1 | AK13: =VLOOKUP($A13&"_"&$C13, DataSource!$A:$AT, 39 + AJ13 - 1, FALSE) -> 【极地生存 Lv.1】对生命值不高于45%的目标，治疗效果+15%。 | AL13: 1 | AM13: =VLOOKUP($A13&"_"&$C13, DataSource!$A:$AT, 44 + AL13 - 1, FALSE) -> 【救援专家 Lv.1】战技饱和性防御成功格挡攻击后，额外获得6终结技能量。
A14: chr_0015_lifeng | B14: =VLOOKUP("chr_0015_lifeng_90", DataSource!$A:$P, 3, FALSE) -> 黎风 | C14: 90 | D14: =VLOOKUP($A14&"_"&$C14, DataSource!$A:$AT, 5, FALSE) -> Lifeng | E14: =VLOOKUP($A14&"_"&$C14, DataSource!$A:$AT, 6, FALSE) -> 近卫 | F14: =VLOOKUP($A14&"_"&$C14, DataSource!$A:$AT, 7, FALSE) -> ENDFIELD INDUSTRIES | G14: =VLOOKUP($A14&"_"&$C14, DataSource!$A:$AT, 8, FALSE) -> 倒地, 物理脆弱, 连击 | H14: =VLOOKUP($A14&"_"&$C14, DataSource!$A:$AT, 9, FALSE) -> 6★ | I14: =VLOOKUP($A14&"_"&$C14, DataSource!$A:$AT, 10, FALSE) -> 长柄武器 | J14: =VLOOKUP($A14&"_"&$C14, DataSource!$A:$AT, 11, FALSE) -> 物理 | K14: =VLOOKUP($A14&"_"&$C14, DataSource!$A:$AT, 12, FALSE) -> 敏捷 | L14: =VLOOKUP($A14&"_"&$C14, DataSource!$A:$AT, 13, FALSE) -> 力量 | M14: =VLOOKUP($A14&"_"&$C14, DataSource!$A:$AT, 14, FALSE) -> 5495 | N14: =VLOOKUP($A14&"_"&$C14, DataSource!$A:$AT, 15, FALSE) -> 312 | O14: =VLOOKUP($A14&"_"&$C14, DataSource!$A:$AT, 16, FALSE) -> 0 | P14: =VLOOKUP($A14&"_"&$C14, DataSource!$A:$AT, 17, FALSE) -> 123.70313486219221 | Q14: =VLOOKUP($A14&"_"&$C14, DataSource!$A:$AT, 18, FALSE) -> 132.28466231853525 | R14: =VLOOKUP($A14&"_"&$C14, DataSource!$A:$AT, 19, FALSE) -> 115.49084788554623 | S14: =VLOOKUP($A14&"_"&$C14, DataSource!$A:$AT, 20, FALSE) -> 117.46581106669464 | T14: =VLOOKUP($A14&"_"&$C14, DataSource!$A:$AT, 21, FALSE) -> 5.0% | U14: =VLOOKUP($A14&"_"&$C14, DataSource!$A:$AT, 22, FALSE) -> 50.0% | V14: =VLOOKUP($A14&"_"&$C14, DataSource!$A:$AT, 23, FALSE) -> 3 | W14: =VLOOKUP($A14&"_"&$C14, DataSource!$A:$AT, 24, FALSE) -> 0.118125 | X14: =VLOOKUP($A14&"_"&$C14, DataSource!$A:$AT, 25, FALSE) -> 1.22704081632653 | Y14: =VLOOKUP($A14&"_"&$C14, DataSource!$A:$AT, 26, FALSE) -> 1.45408163265306 | Z14: =VLOOKUP($A14&"_"&$C14, DataSource!$A:$AT, 27, FALSE) -> 4 | AA14: =VLOOKUP($A14&"_"&$C14, DataSource!$A:$AT, 28, FALSE) -> 【破执】战技荡浊身施加的物理脆弱效果+5%，且对破防层数不超过2层的敌人仍然能触发此额外效果。 | AB14: =VLOOKUP($A14&"_"&$C14, DataSource!$A:$AT, 29, FALSE) -> 【修身】全能力+15。 | AC14: =VLOOKUP($A14&"_"&$C14, DataSource!$A:$AT, 30, FALSE) -> 【养性】天赋顿悟效果加强：每点智识和意志使攻击力额外+0.05%。 | AD14: =VLOOKUP($A14&"_"&$C14, DataSource!$A:$AT, 31, FALSE) -> 【刹那】终结技不动心所需的终结技能量-15%。 | AE14: =VLOOKUP($A14&"_"&$C14, DataSource!$A:$AT, 32, FALSE) -> 【不懈】天赋伏魔效果加强：每隔15秒，下一次触发时额外造成攻击力250%的物理伤害和5点失衡。 | AF14: =VLOOKUP($A14&"_"&$C14, DataSource!$A:$AT, 33, FALSE) -> 【游刃】干员敏捷能力值提升15。 | AG14: =VLOOKUP($A14&"_"&$C14, DataSource!$A:$AT, 34, FALSE) -> 【游刃】干员敏捷能力值提升10。 | AH14: =VLOOKUP($A14&"_"&$C14, DataSource!$A:$AT, 35, FALSE) -> 【游刃】干员敏捷能力值提升15。 | AI14: =VLOOKUP($A14&"_"&$C14, DataSource!$A:$AT, 36, FALSE) -> 【游刃】干员敏捷能力值提升20。 | AJ14: 1 | AK14: =VLOOKUP($A14&"_"&$C14, DataSource!$A:$AT, 39 + AJ14 - 1, FALSE) -> 【顿悟 Lv.1】每点智识和意志都会使攻击力额外+0.10%。 | AL14: 1 | AM14: =VLOOKUP($A14&"_"&$C14, DataSource!$A:$AT, 44 + AL14 - 1, FALSE) -> 【伏魔 Lv.1】每当自身造成倒地时，额外造成攻击力50%的物理伤害。
